Workbook
Name companys: Stats!$B$4:$B$15
Name HERO: format!$A$32:$A$37
Name Relic_Names: Stats!$B$74:$B$87
Name Relics: Stats!$B$74:$L$87
Name ROW1_TRAITS: 'exclusion traits'!$N$3:$N$55
Name ROW10_TRAITS: 'exclusion traits'!$ES$3:$ES$56
Name ROW11_TRAITS: 'exclusion traits'!$FH$3:$FH$56
Name ROW2_TRAITS: 'exclusion traits'!$AC$3:$AC$55
Name ROW3_TRAITS: 'exclusion traits'!$AR$3:$AR$55
Name ROW4_TRAITS: 'exclusion traits'!$BG$3:$BG$55
Name ROW5_TRAITS: 'exclusion traits'!$BV$3:$BV$55
Name ROW6_TRAITS: 'exclusion traits'!$CK$3:$CK$55
Name ROW7_TRAITS: 'exclusion traits'!$CZ$3:$CZ$56
Name ROW8_TRAITS: 'exclusion traits'!$DO$3:$DO$56
Name ROW9_TRAITS: 'exclusion traits'!$ED$3:$ED$56
Name sorted: sort!$A$4:$R$30
Name stats: Stats!$B$4:$K$15
Name Strats: Stats!$B$91:$K$98
Name traits: Stats!$B$18:$J$70
Name TRAITS_ROW12: 'exclusion traits'!$FW$3:$FW$56
Name TRAITS_ROW13: 'exclusion traits'!$GL$3:$GL$56
Name TRAITS_ROW14: 'exclusion traits'!$HA$3:$HA$56
Name TRAITS_ROW15: 'exclusion traits'!$HP$3:$HP$56
Name TRAITS_ROW16: 'exclusion traits'!$IE$3:$IE$56
Name TRAITS_ROW17: 'exclusion traits'!$IT$3:$IT$56
Name TRAITS_ROW18: 'exclusion traits'!$JI$3:$JI$56
Name TRAITS_ROW19: 'exclusion traits'!$JX$3:$JX$56
Name TRAITS_ROW20: 'exclusion traits'!$KM$3:$KM$56
Name TRAITS_ROW21: 'exclusion traits'!$LB$3:$LB$56
Name TRAITS_ROW22: 'exclusion traits'!$LQ$3:$LQ$56
Name TRAITS_ROW23: 'exclusion traits'!$MF$3:$MF$56
Name TRAITS_ROW24: 'exclusion traits'!$MU$3:$MU$56
Name TRAITS_ROW25: 'exclusion traits'!$NJ$3:$NJ$56

Sheet Builder
B2: Army name | L2: Strategy 1 | M2: Strategy 2 | N2: Strategy 3 | P2: Points total | R2: =SUM(R5:R28)+SUM(AX3:AX5) -> 0 | AW2: Strategies | AX2: Cost | BC2: 1 | BD2: 9 | BG2: 1 | BH2: 2 | BI2: 3 | BJ2: 4 | BK2: 5 | BL2: 6 | BM2: 7 | BN2: 8 | BO2: 9 | BQ2: 1 | BR2: 2 | BS2: 3 | BT2: 4 | BU2: 5 | BV2: 6 | BW2: 7 | BX2: 8 | BY2: 9 | CA2: 1 | CB2: 2 | CC2: 3 | CD2: 4 | CE2: 5 | CF2: 6 | CG2: 7 | CH2: 8 | CI2: 9 | CK2: 1 | CL2: 2 | CM2: 3 | CN2: 4 | CO2: 5 | CP2: 6 | CQ2: 7 | CR2: 8 | CS2: 9 | CU2: 1 | CV2: 2 | CW2: 3 | CX2: 4 | CY2: 5 | CZ2: 6 | DA2: 7 | DB2: 8 | DC2: 9 | DF2: 1 | DG2: 2 | DH2: 3 | DI2: 4 | DJ2: 5 | DK2: 6 | DL2: 7 | DM2: 8 | DN2: 9
G3: Sht | AD3: company | AE3: trait1 | AF3: trai2 | AG3: trait3 | AH3: sum | AI3: count | AJ3: max | AM3: Calc | AW3: =L3 -> 0 | AX3: =IFERROR(VLOOKUP($AW3,Strats,9,FALSE),0) -> 0 | AY3: =IFERROR(VLOOKUP($AW3,Strats,10,FALSE),0) -> 0 | BC3: Relics | BG3: BASE | BQ3: RACIAL | CA3: trait1 | CK3: trait2 | CU3: trait 3 | DF3: relic
B4: Unit name | C4: Company | D4: Res | E4: Mov | F4: Mel | G4: short | H4: long | I4: Def | J4: Com | K4: Racial | L4: Trait1 | M4: Trait2 | N4: Trait3 | O4: Relic | P4: Cost | Q4: # Bases | R4: Total | U4: Company | AB4: Mage-lord | AC4: =IFERROR(VLOOKUP($AB4,format!$C$5:$Q$30,1,FALSE),0) -> 0 | AD4: =IFERROR(VLOOKUP($AB4,format!$C$5:$Q$30,15,FALSE),0) -> 0 | AH4: =SUM(AD4:AG4) -> 0 | AI4: =COUNTIF(format!$C$5:$C$29,Builder!AB4) -> 0 | AJ4: =IF(AI4>AH4,AI4,AH4) -> 0 | AW4: =M3 -> 0 | AX4: =IFERROR(VLOOKUP($AW4,Strats,9,FALSE),0) -> 0 | AY4: =IFERROR(VLOOKUP($AW4,Strats,10,FALSE),0) -> 0
A5: 1 | D5: =AM7 -> 0 | E5: =AN7 -> 0 | F5: =AO7 -> 0 | G5: =AP7 -> 0 | H5: =AQ7 -> 0 | I5: =AR7 -> 0 | J5: =AS7 -> 0 | P5: =BO7+BY7+CI7+CS7+DC7+BD7 -> 0 | R5: =Q5*P5 -> 0 | U5: =IF(C5=$U$2,0,IFERROR(VLOOKUP($C5,Stats!$B$4:$B$8,1,FALSE),"Company")) -> 0 | V5: =IF(C5=$U$2,0,IFERROR(VLOOKUP(K5,Stats!$B$24:$B$27,1,FALSE),"Company")) -> 0 | W5: =IF(D5=$U$2,0,IFERROR(VLOOKUP(L5,Stats!$B$24:$B$27,1,FALSE),"Company")) -> 0 | X5: =IF(E5=$U$2,0,IFERROR(VLOOKUP(M5,Stats!$B$24:$B$27,1,FALSE),"Company")) -> 0 | Y5: =IF(F5=$U$2,0,IFERROR(VLOOKUP(N5,Stats!$B$24:$B$27,1,FALSE),"Company")) -> 0 | Z5: =COUNTIF(U5:Y5,$U$4) -> 0 | AB5: Warlord | AC5: =IFERROR(VLOOKUP($AB5,format!$C$5:$Q$30,1,FALSE),0) -> 0 | AD5: =IFERROR(VLOOKUP($AB5,format!$C$5:$Q$30,15,FALSE),0) -> 0 | AH5: =SUM(AD5:AG5) -> 0 | AI5: =COUNTIF(format!$C$5:$C$29,Builder!AB5) -> 0 | AJ5: =IF(AI5>AH5,AI5,AH5) -> 0 | AW5: =N3 -> 0 | AX5: =IFERROR(VLOOKUP($AW5,Strats,9,FALSE),0) -> 0 | AY5: =IFERROR(VLOOKUP($AW5,Strats,10,FALSE),0) -> 0
A6: 2 | D6: =AM8 -> 0 | E6: =AN8 -> 0 | F6: =AO8 -> 0 | G6: =AP8 -> 0 | H6: =AQ8 -> 0 | I6: =AR8 -> 0 | J6: =AS8 -> 0 | P6: =BO8+BY8+CI8+CS8+DC8+BD8 -> 0 | R6: =Q6*P6 -> 0 | U6: =IF(C6=$U$2,0,IFERROR(VLOOKUP($C6,Stats!$B$4:$B$8,1,FALSE),"Company")) -> 0 | V6: =IF(C6=$U$2,0,IFERROR(VLOOKUP(K6,Stats!$B$24:$B$27,1,FALSE),"Company")) -> 0 | W6: =IF(D6=$U$2,0,IFERROR(VLOOKUP(L6,Stats!$B$24:$B$27,1,FALSE),"Company")) -> 0 | X6: =IF(E6=$U$2,0,IFERROR(VLOOKUP(M6,Stats!$B$24:$B$27,1,FALSE),"Company")) -> 0 | Y6: =IF(F6=$U$2,0,IFERROR(VLOOKUP(N6,Stats!$B$24:$B$27,1,FALSE),"Company")) -> 0 | Z6: =COUNTIF(U6:Y6,$U$4) -> 0 | AB6: Captain | AC6: =IFERROR(VLOOKUP($AB6,format!$C$5:$Q$30,1,FALSE),0) -> 0 | AD6: =IFERROR(VLOOKUP($AB6,format!$C$5:$Q$30,15,FALSE),0) -> 0 | AH6: =SUM(AD6:AG6) -> 0 | AI6: =COUNTIF(format!$C$5:$C$29,Builder!AB6) -> 0 | AJ6: =IF(AI6>AH6,AI6,AH6) -> 0
A7: 3 | D7: =AM9 -> 0 | E7: =AN9 -> 0 | F7: =AO9 -> 0 | G7: =AP9 -> 0 | H7: =AQ9 -> 0 | I7: =AR9 -> 0 | J7: =AS9 -> 0 | P7: =BO9+BY9+CI9+CS9+DC9+BD9 -> 0 | R7: =Q7*P7 -> 0 | U7: =IF(C7=$U$2,0,IFERROR(VLOOKUP($C7,Stats!$B$4:$B$8,1,FALSE),"Company")) -> 0 | V7: =IF(C7=$U$2,0,IFERROR(VLOOKUP(K7,Stats!$B$24:$B$27,1,FALSE),"Company")) -> 0 | W7: =IF(D7=$U$2,0,IFERROR(VLOOKUP(L7,Stats!$B$24:$B$27,1,FALSE),"Company")) -> 0 | X7: =IF(E7=$U$2,0,IFERROR(VLOOKUP(M7,Stats!$B$24:$B$27,1,FALSE),"Company")) -> 0 | Y7: =IF(F7=$U$2,0,IFERROR(VLOOKUP(N7,Stats!$B$24:$B$27,1,FALSE),"Company")) -> 0 | Z7: =COUNTIF(U7:Y7,$U$4) -> 0 | AB7: Magic-user | AC7: =IFERROR(VLOOKUP($AB7,format!$C$5:$Q$30,1,FALSE),0) -> 0 | AD7: =IFERROR(VLOOKUP($AB7,format!$C$5:$Q$30,15,FALSE),0) -> 0 | AH7: =SUM(AD7:AG7) -> 0 | AI7: =COUNTIF(format!$C$5:$C$29,Builder!AB7) -> 0 | AJ7: =IF(AI7>AH7,AI7,AH7) -> 0 | AM7: =BH7+BR7+CB7+CL7+CV7+DG7 -> 0 | AN7: =BI7+BS7+CC7+CM7+CW7+DH7 -> 0 | AO7: =BJ7+BT7+CD7+CN7+CX7+DI7 -> 0 | AP7: =IF(MAX(BK7,BU7,CE7,CO7,CY7,DJ7)>1,MAX(BK7,BU7,CE7,CO7,CY7,DJ7),BK7+BU7+CE7+CO7+CY7+DJ7) -> 0 | AQ7: =IF(AND(C5="Ordnance battery",(OR(K5="Shooting (mixed)",L5="Shooting (mixed)",M5="Shooting (mixed)",N5="Shooting (mixed)"))),1,IF(MAX(BL7,BV7,CF7,CP7,CZ7,DK7)>1,MAX(BL7,BV7,CF7,CP7,CZ7,DK7),BL7+BV7+CF7+CP7+CZ7+DK7)) -> 0 | AR7: =BM7+BW7+CG7+CQ7+DA7+DL7 -> 0 | AS7: =BN7+BX7+CH7+CR7+DB7+DM7 -> 0 | BC7: =IFERROR(VLOOKUP($O5,Relics,BC$2,FALSE),0) -> 0 | BD7: =IFERROR(VLOOKUP($O5,Relics,BD$2,FALSE),0) -> 0 | BG7: =IFERROR(VLOOKUP($C5,stats,BG$2,FALSE),0) -> 0 | BH7: =IFERROR(VLOOKUP($C5,stats,BH$2,FALSE),0) -> 0 | BI7: =IFERROR(VLOOKUP($C5,stats,BI$2,FALSE),0) -> 0 | BJ7: =IFERROR(VLOOKUP($C5,stats,BJ$2,FALSE),0) -> 0 | BK7: =IFERROR(VLOOKUP($C5,stats,BK$2,FALSE),0) -> 0 | BL7: =IFERROR(VLOOKUP($C5,stats,BL$2,FALSE),0) -> 0 | BM7: =IFERROR(VLOOKUP($C5,stats,BM$2,FALSE),0) -> 0 | BN7: =IFERROR(VLOOKUP($C5,stats,BN$2,FALSE),0) -> 0 | BO7: =IFERROR(VLOOKUP($C5,stats,BO$2,FALSE),0) -> 0 | BQ7: =IFERROR(VLOOKUP($K5,traits,BQ$2,FALSE),0) -> 0 | BR7: =IFERROR(VLOOKUP($K5,traits,BR$2,FALSE),0) -> 0 | BS7: =IFERROR(VLOOKUP($K5,traits,BS$2,FALSE),0) -> 0 | BT7: =IFERROR(VLOOKUP($K5,traits,BT$2,FALSE),0) -> 0 | BU7: =IFERROR(VLOOKUP($K5,traits,BU$2,FALSE),0) -> 0 | BV7: =IFERROR(VLOOKUP($K5,traits,BV$2,FALSE),0) -> 0 | BW7: =IFERROR(VLOOKUP($K5,traits,BW$2,FALSE),0) -> 0 | BX7: =IFERROR(VLOOKUP($K5,traits,BX$2,FALSE),0) -> 0 | BY7: =IFERROR(VLOOKUP($K5,traits,BY$2,FALSE),0) -> 0 | CA7: =IFERROR(VLOOKUP($L5,traits,CA$2,FALSE),0) -> 0 | CB7: =IFERROR(VLOOKUP($L5,traits,CB$2,FALSE),0) -> 0 | CC7: =IFERROR(VLOOKUP($L5,traits,CC$2,FALSE),0) -> 0 | CD7: =IFERROR(VLOOKUP($L5,traits,CD$2,FALSE),0) -> 0 | CE7: =IFERROR(VLOOKUP($L5,traits,CE$2,FALSE),0) -> 0 | CF7: =IFERROR(VLOOKUP($L5,traits,CF$2,FALSE),0) -> 0 | CG7: =IFERROR(VLOOKUP($L5,traits,CG$2,FALSE),0) -> 0 | CH7: =IFERROR(VLOOKUP($L5,traits,CH$2,FALSE),0) -> 0 | CI7: =IFERROR(VLOOKUP($L5,traits,CI$2,FALSE),0) -> 0 | CK7: =IFERROR(VLOOKUP($M5,traits,CK$2,FALSE),0) -> 0 | CL7: =IFERROR(VLOOKUP($M5,traits,CL$2,FALSE),0) -> 0 | CM7: =IFERROR(VLOOKUP($M5,traits,CM$2,FALSE),0) -> 0 | CN7: =IFERROR(VLOOKUP($M5,traits,CN$2,FALSE),0) -> 0 | CO7: =IFERROR(VLOOKUP($M5,traits,CO$2,FALSE),0) -> 0 | CP7: =IFERROR(VLOOKUP($M5,traits,CP$2,FALSE),0) -> 0 | CQ7: =IFERROR(VLOOKUP($M5,traits,CQ$2,FALSE),0) -> 0 | CR7: =IFERROR(VLOOKUP($M5,traits,CR$2,FALSE),0) -> 0 | CS7: =IFERROR(VLOOKUP($M5,traits,CS$2,FALSE),0) -> 0 | CU7: =IFERROR(VLOOKUP($N5,traits,CU$2,FALSE),0) -> 0 | CV7: =IFERROR(VLOOKUP($N5,traits,CV$2,FALSE),0) -> 0 | CW7: =IFERROR(VLOOKUP($N5,traits,CW$2,FALSE),0) -> 0 | CX7: =IFERROR(VLOOKUP($N5,traits,CX$2,FALSE),0) -> 0 | CY7: =IFERROR(VLOOKUP($N5,traits,CY$2,FALSE),0) -> 0 | CZ7: =IFERROR(VLOOKUP($N5,traits,CZ$2,FALSE),0) -> 0 | DA7: =IFERROR(VLOOKUP($N5,traits,DA$2,FALSE),0) -> 0 | DB7: =IFERROR(VLOOKUP($N5,traits,DB$2,FALSE),0) -> 0 | DC7: =IFERROR(VLOOKUP($N5,traits,DC$2,FALSE),0) -> 0 | DF7: =IFERROR(VLOOKUP($O5,Relics,DF$2,FALSE),0) -> 0 | DG7: =IFERROR(VLOOKUP($O5,Relics,DG$2,FALSE),0) -> 0 | DH7: =IFERROR(VLOOKUP($O5,Relics,DH$2,FALSE),0) -> 0 | DI7: =IFERROR(VLOOKUP($O5,Relics,DI$2,FALSE),0) -> 0 | DJ7: =IFERROR(VLOOKUP($O5,Relics,DJ$2,FALSE),0) -> 0 | DK7: =IFERROR(VLOOKUP($O5,Relics,DK$2,FALSE),0) -> 0 | DL7: =IFERROR(VLOOKUP($O5,Relics,DL$2,FALSE),0) -> 0 | DM7: =IFERROR(VLOOKUP($O5,Relics,DM$2,FALSE),0) -> 0 | DN7: =IFERROR(VLOOKUP($O5,Relics,DN$2,FALSE),0) -> 0
A8: 4 | D8: =AM10 -> 0 | E8: =AN10 -> 0 | F8: =AO10 -> 0 | G8: =AP10 -> 0 | H8: =AQ10 -> 0 | I8: =AR10 -> 0 | J8: =AS10 -> 0 | P8: =BO10+BY10+CI10+CS10+DC10+BD10 -> 0 | R8: =Q8*P8 -> 0 | U8: =IF(C8=$U$2,0,IFERROR(VLOOKUP($C8,Stats!$B$4:$B$8,1,FALSE),"Company")) -> 0 | V8: =IF(C8=$U$2,0,IFERROR(VLOOKUP(K8,Stats!$B$24:$B$27,1,FALSE),"Company")) -> 0 | W8: =IF(D8=$U$2,0,IFERROR(VLOOKUP(L8,Stats!$B$24:$B$27,1,FALSE),"Company")) -> 0 | X8: =IF(E8=$U$2,0,IFERROR(VLOOKUP(M8,Stats!$B$24:$B$27,1,FALSE),"Company")) -> 0 | Y8: =IF(F8=$U$2,0,IFERROR(VLOOKUP(N8,Stats!$B$24:$B$27,1,FALSE),"Company")) -> 0 | Z8: =COUNTIF(U8:Y8,$U$4) -> 0 | AB8: Rogue | AC8: =IFERROR(VLOOKUP($AB8,format!$C$5:$Q$30,1,FALSE),0) -> 0 | AD8: =IFERROR(VLOOKUP($AB8,format!$C$5:$Q$30,15,FALSE),0) -> 0 | AH8: =SUM(AD8:AG8) -> 0 | AI8: =COUNTIF(format!$C$5:$C$29,Builder!AB8) -> 0 | AJ8: =IF(AI8>AH8,AI8,AH8) -> 0 | AM8: =BH8+BR8+CB8+CL8+CV8+DG8 -> 0 | AN8: =BI8+BS8+CC8+CM8+CW8+DH8 -> 0 | AO8: =BJ8+BT8+CD8+CN8+CX8+DI8 -> 0 | AP8: =IF(MAX(BK8,BU8,CE8,CO8,CY8,DJ8)>1,MAX(BK8,BU8,CE8,CO8,CY8,DJ8),BK8+BU8+CE8+CO8+CY8+DJ8) -> 0 | AQ8: =IF(AND(C6="Ordnance battery",(OR(K6="Shooting (mixed)",L6="Shooting (mixed)",M6="Shooting (mixed)",N6="Shooting (mixed)"))),1,IF(MAX(BL8,BV8,CF8,CP8,CZ8,DK8)>1,MAX(BL8,BV8,CF8,CP8,CZ8,DK8),BL8+BV8+CF8+CP8+CZ8+DK8)) -> 0 | AR8: =BM8+BW8+CG8+CQ8+DA8+DL8 -> 0 | AS8: =BN8+BX8+CH8+CR8+DB8+DM8 -> 0 | BC8: =IFERROR(VLOOKUP($O6,Relics,BC$2,FALSE),0) -> 0 | BD8: =IFERROR(VLOOKUP($O6,Relics,BD$2,FALSE),0) -> 0 | BG8: =IFERROR(VLOOKUP($C6,stats,BG$2,FALSE),0) -> 0 | BH8: =IFERROR(VLOOKUP($C6,stats,BH$2,FALSE),0) -> 0 | BI8: =IFERROR(VLOOKUP($C6,stats,BI$2,FALSE),0) -> 0 | BJ8: =IFERROR(VLOOKUP($C6,stats,BJ$2,FALSE),0) -> 0 | BK8: =IFERROR(VLOOKUP($C6,stats,BK$2,FALSE),0) -> 0 | BL8: =IFERROR(VLOOKUP($C6,stats,BL$2,FALSE),0) -> 0 | BM8: =IFERROR(VLOOKUP($C6,stats,BM$2,FALSE),0) -> 0 | BN8: =IFERROR(VLOOKUP($C6,stats,BN$2,FALSE),0) -> 0 | BO8: =IFERROR(VLOOKUP($C6,stats,BO$2,FALSE),0) -> 0 | BQ8: =IFERROR(VLOOKUP($K6,traits,BQ$2,FALSE),0) -> 0 | BR8: =IFERROR(VLOOKUP($K6,traits,BR$2,FALSE),0) -> 0 | BS8: =IFERROR(VLOOKUP($K6,traits,BS$2,FALSE),0) -> 0 | BT8: =IFERROR(VLOOKUP($K6,traits,BT$2,FALSE),0) -> 0 | BU8: =IFERROR(VLOOKUP($K6,traits,BU$2,FALSE),0) -> 0 | BV8: =IFERROR(VLOOKUP($K6,traits,BV$2,FALSE),0) -> 0 | BW8: =IFERROR(VLOOKUP($K6,traits,BW$2,FALSE),0) -> 0 | BX8: =IFERROR(VLOOKUP($K6,traits,BX$2,FALSE),0) -> 0 | BY8: =IFERROR(VLOOKUP($K6,traits,BY$2,FALSE),0) -> 0 | CA8: =IFERROR(VLOOKUP($L6,traits,CA$2,FALSE),0) -> 0 | CB8: =IFERROR(VLOOKUP($L6,traits,CB$2,FALSE),0) -> 0 | CC8: =IFERROR(VLOOKUP($L6,traits,CC$2,FALSE),0) -> 0 | CD8: =IFERROR(VLOOKUP($L6,traits,CD$2,FALSE),0) -> 0 | CE8: =IFERROR(VLOOKUP($L6,traits,CE$2,FALSE),0) -> 0 | CF8: =IFERROR(VLOOKUP($L6,traits,CF$2,FALSE),0) -> 0 | CG8: =IFERROR(VLOOKUP($L6,traits,CG$2,FALSE),0) -> 0 | CH8: =IFERROR(VLOOKUP($L6,traits,CH$2,FALSE),0) -> 0 | CI8: =IFERROR(VLOOKUP($L6,traits,CI$2,FALSE),0) -> 0 | CK8: =IFERROR(VLOOKUP($M6,traits,CK$2,FALSE),0) -> 0 | CL8: =IFERROR(VLOOKUP($M6,traits,CL$2,FALSE),0) -> 0 | CM8: =IFERROR(VLOOKUP($M6,traits,CM$2,FALSE),0) -> 0 | CN8: =IFERROR(VLOOKUP($M6,traits,CN$2,FALSE),0) -> 0 | CO8: =IFERROR(VLOOKUP($M6,traits,CO$2,FALSE),0) -> 0 | CP8: =IFERROR(VLOOKUP($M6,traits,CP$2,FALSE),0) -> 0 | CQ8: =IFERROR(VLOOKUP($M6,traits,CQ$2,FALSE),0) -> 0 | CR8: =IFERROR(VLOOKUP($M6,traits,CR$2,FALSE),0) -> 0 | CS8: =IFERROR(VLOOKUP($M6,traits,CS$2,FALSE),0) -> 0 | CU8: =IFERROR(VLOOKUP($N6,traits,CU$2,FALSE),0) -> 0 | CV8: =IFERROR(VLOOKUP($N6,traits,CV$2,FALSE),0) -> 0 | CW8: =IFERROR(VLOOKUP($N6,traits,CW$2,FALSE),0) -> 0 | CX8: =IFERROR(VLOOKUP($N6,traits,CX$2,FALSE),0) -> 0 | CY8: =IFERROR(VLOOKUP($N6,traits,CY$2,FALSE),0) -> 0 | CZ8: =IFERROR(VLOOKUP($N6,traits,CZ$2,FALSE),0) -> 0 | DA8: =IFERROR(VLOOKUP($N6,traits,DA$2,FALSE),0) -> 0 | DB8: =IFERROR(VLOOKUP($N6,traits,DB$2,FALSE),0) -> 0 | DC8: =IFERROR(VLOOKUP($N6,traits,DC$2,FALSE),0) -> 0 | DF8: =IFERROR(VLOOKUP($O6,Relics,DF$2,FALSE),0) -> 0 | DG8: =IFERROR(VLOOKUP($O6,Relics,DG$2,FALSE),0) -> 0 | DH8: =IFERROR(VLOOKUP($O6,Relics,DH$2,FALSE),0) -> 0 | DI8: =IFERROR(VLOOKUP($O6,Relics,DI$2,FALSE),0) -> 0 | DJ8: =IFERROR(VLOOKUP($O6,Relics,DJ$2,FALSE),0) -> 0 | DK8: =IFERROR(VLOOKUP($O6,Relics,DK$2,FALSE),0) -> 0 | DL8: =IFERROR(VLOOKUP($O6,Relics,DL$2,FALSE),0) -> 0 | DM8: =IFERROR(VLOOKUP($O6,Relics,DM$2,FALSE),0) -> 0 | DN8: =IFERROR(VLOOKUP($O6,Relics,DN$2,FALSE),0) -> 0
A9: 5 | D9: =AM11 -> 0 | E9: =AN11 -> 0 | F9: =AO11 -> 0 | G9: =AP11 -> 0 | H9: =AQ11 -> 0 | I9: =AR11 -> 0 | J9: =AS11 -> 0 | P9: =BO11+BY11+CI11+CS11+DC11+BD11 -> 0 | R9: =Q9*P9 -> 0 | U9: =IF(C9=$U$2,0,IFERROR(VLOOKUP($C9,Stats!$B$4:$B$8,1,FALSE),"Company")) -> 0 | V9: =IF(C9=$U$2,0,IFERROR(VLOOKUP(K9,Stats!$B$24:$B$27,1,FALSE),"Company")) -> 0 | W9: =IF(D9=$U$2,0,IFERROR(VLOOKUP(L9,Stats!$B$24:$B$27,1,FALSE),"Company")) -> 0 | X9: =IF(E9=$U$2,0,IFERROR(VLOOKUP(M9,Stats!$B$24:$B$27,1,FALSE),"Company")) -> 0 | Y9: =IF(F9=$U$2,0,IFERROR(VLOOKUP(N9,Stats!$B$24:$B$27,1,FALSE),"Company")) -> 0 | Z9: =COUNTIF(U9:Y9,$U$4) -> 0 | AB9: Character (Warlord) | AC9: =IFERROR(VLOOKUP($AB9,format!$C$5:$Q$30,1,FALSE),0) -> 0 | AD9: =IFERROR(VLOOKUP($AB9,format!$C$5:$Q$30,15,FALSE),0) -> 0 | AE9: =IFERROR(VLOOKUP($AB9,format!$L$5:$Q$30,6,FALSE),0) -> 0 | AF9: =IFERROR(VLOOKUP($AB9,format!$M$5:$Q$30,5,FALSE),0) -> 0 | AG9: =IFERROR(VLOOKUP($AB9,format!$N$5:$Q$30,4,FALSE),0) -> 0 | AH9: =SUM(AD9:AG9) -> 0 | AI9: =COUNTIF(format!$L$5:$N$30,Builder!AB9) -> 0 | AJ9: =IF(AI9>AH9,AI9,AH9) -> 0 | AM9: =BH9+BR9+CB9+CL9+CV9+DG9 -> 0 | AN9: =BI9+BS9+CC9+CM9+CW9+DH9 -> 0 | AO9: =BJ9+BT9+CD9+CN9+CX9+DI9 -> 0 | AP9: =IF(MAX(BK9,BU9,CE9,CO9,CY9,DJ9)>1,MAX(BK9,BU9,CE9,CO9,CY9,DJ9),BK9+BU9+CE9+CO9+CY9+DJ9) -> 0 | AQ9: =IF(AND(C7="Ordnance battery",(OR(K7="Shooting (mixed)",L7="Shooting (mixed)",M7="Shooting (mixed)",N7="Shooting (mixed)"))),1,IF(MAX(BL9,BV9,CF9,CP9,CZ9,DK9)>1,MAX(BL9,BV9,CF9,CP9,CZ9,DK9),BL9+BV9+CF9+CP9+CZ9+DK9)) -> 0 | AR9: =BM9+BW9+CG9+CQ9+DA9+DL9 -> 0 | AS9: =BN9+BX9+CH9+CR9+DB9+DM9 -> 0 | BC9: =IFERROR(VLOOKUP($O7,Relics,BC$2,FALSE),0) -> 0 | BD9: =IFERROR(VLOOKUP($O7,Relics,BD$2,FALSE),0) -> 0 | BG9: =IFERROR(VLOOKUP($C7,stats,BG$2,FALSE),0) -> 0 | BH9: =IFERROR(VLOOKUP($C7,stats,BH$2,FALSE),0) -> 0 | BI9: =IFERROR(VLOOKUP($C7,stats,BI$2,FALSE),0) -> 0 | BJ9: =IFERROR(VLOOKUP($C7,stats,BJ$2,FALSE),0) -> 0 | BK9: =IFERROR(VLOOKUP($C7,stats,BK$2,FALSE),0) -> 0 | BL9: =IFERROR(VLOOKUP($C7,stats,BL$2,FALSE),0) -> 0 | BM9: =IFERROR(VLOOKUP($C7,stats,BM$2,FALSE),0) -> 0 | BN9: =IFERROR(VLOOKUP($C7,stats,BN$2,FALSE),0) -> 0 | BO9: =IFERROR(VLOOKUP($C7,stats,BO$2,FALSE),0) -> 0 | BQ9: =IFERROR(VLOOKUP($K7,traits,BQ$2,FALSE),0) -> 0 | BR9: =IFERROR(VLOOKUP($K7,traits,BR$2,FALSE),0) -> 0 | BS9: =IFERROR(VLOOKUP($K7,traits,BS$2,FALSE),0) -> 0 | BT9: =IFERROR(VLOOKUP($K7,traits,BT$2,FALSE),0) -> 0 | BU9: =IFERROR(VLOOKUP($K7,traits,BU$2,FALSE),0) -> 0 | BV9: =IFERROR(VLOOKUP($K7,traits,BV$2,FALSE),0) -> 0 | BW9: =IFERROR(VLOOKUP($K7,traits,BW$2,FALSE),0) -> 0 | BX9: =IFERROR(VLOOKUP($K7,traits,BX$2,FALSE),0) -> 0 | BY9: =IFERROR(VLOOKUP($K7,traits,BY$2,FALSE),0) -> 0 | CA9: =IFERROR(VLOOKUP($L7,traits,CA$2,FALSE),0) -> 0 | CB9: =IFERROR(VLOOKUP($L7,traits,CB$2,FALSE),0) -> 0 | CC9: =IFERROR(VLOOKUP($L7,traits,CC$2,FALSE),0) -> 0 | CD9: =IFERROR(VLOOKUP($L7,traits,CD$2,FALSE),0) -> 0 | CE9: =IFERROR(VLOOKUP($L7,traits,CE$2,FALSE),0) -> 0 | CF9: =IFERROR(VLOOKUP($L7,traits,CF$2,FALSE),0) -> 0 | CG9: =IFERROR(VLOOKUP($L7,traits,CG$2,FALSE),0) -> 0 | CH9: =IFERROR(VLOOKUP($L7,traits,CH$2,FALSE),0) -> 0 | CI9: =IFERROR(VLOOKUP($L7,traits,CI$2,FALSE),0) -> 0 | CK9: =IFERROR(VLOOKUP($M7,traits,CK$2,FALSE),0) -> 0 | CL9: =IFERROR(VLOOKUP($M7,traits,CL$2,FALSE),0) -> 0 | CM9: =IFERROR(VLOOKUP($M7,traits,CM$2,FALSE),0) -> 0 | CN9: =IFERROR(VLOOKUP($M7,traits,CN$2,FALSE),0) -> 0 | CO9: =IFERROR(VLOOKUP($M7,traits,CO$2,FALSE),0) -> 0 | CP9: =IFERROR(VLOOKUP($M7,traits,CP$2,FALSE),0) -> 0 | CQ9: =IFERROR(VLOOKUP($M7,traits,CQ$2,FALSE),0) -> 0 | CR9: =IFERROR(VLOOKUP($M7,traits,CR$2,FALSE),0) -> 0 | CS9: =IFERROR(VLOOKUP($M7,traits,CS$2,FALSE),0) -> 0 | CU9: =IFERROR(VLOOKUP($N7,traits,CU$2,FALSE),0) -> 0 | CV9: =IFERROR(VLOOKUP($N7,traits,CV$2,FALSE),0) -> 0 | CW9: =IFERROR(VLOOKUP($N7,traits,CW$2,FALSE),0) -> 0 | CX9: =IFERROR(VLOOKUP($N7,traits,CX$2,FALSE),0) -> 0 | CY9: =IFERROR(VLOOKUP($N7,traits,CY$2,FALSE),0) -> 0 | CZ9: =IFERROR(VLOOKUP($N7,traits,CZ$2,FALSE),0) -> 0 | DA9: =IFERROR(VLOOKUP($N7,traits,DA$2,FALSE),0) -> 0 | DB9: =IFERROR(VLOOKUP($N7,traits,DB$2,FALSE),0) -> 0 | DC9: =IFERROR(VLOOKUP($N7,traits,DC$2,FALSE),0) -> 0 | DF9: =IFERROR(VLOOKUP($O7,Relics,DF$2,FALSE),0) -> 0 | DG9: =IFERROR(VLOOKUP($O7,Relics,DG$2,FALSE),0) -> 0 | DH9: =IFERROR(VLOOKUP($O7,Relics,DH$2,FALSE),0) -> 0 | DI9: =IFERROR(VLOOKUP($O7,Relics,DI$2,FALSE),0) -> 0 | DJ9: =IFERROR(VLOOKUP($O7,Relics,DJ$2,FALSE),0) -> 0 | DK9: =IFERROR(VLOOKUP($O7,Relics,DK$2,FALSE),0) -> 0 | DL9: =IFERROR(VLOOKUP($O7,Relics,DL$2,FALSE),0) -> 0 | DM9: =IFERROR(VLOOKUP($O7,Relics,DM$2,FALSE),0) -> 0 | DN9: =IFERROR(VLOOKUP($O7,Relics,DN$2,FALSE),0) -> 0
A10: 6 | D10: =AM12 -> 0 | E10: =AN12 -> 0 | F10: =AO12 -> 0 | G10: =AP12 -> 0 | H10: =AQ12 -> 0 | I10: =AR12 -> 0 | J10: =AS12 -> 0 | P10: =BO12+BY12+CI12+CS12+DC12+BD12 -> 0 | R10: =Q10*P10 -> 0 | U10: =IF(C10=$U$2,0,IFERROR(VLOOKUP($C10,Stats!$B$4:$B$8,1,FALSE),"Company")) -> 0 | V10: =IF(C10=$U$2,0,IFERROR(VLOOKUP(K10,Stats!$B$24:$B$27,1,FALSE),"Company")) -> 0 | W10: =IF(D10=$U$2,0,IFERROR(VLOOKUP(L10,Stats!$B$24:$B$27,1,FALSE),"Company")) -> 0 | X10: =IF(E10=$U$2,0,IFERROR(VLOOKUP(M10,Stats!$B$24:$B$27,1,FALSE),"Company")) -> 0 | Y10: =IF(F10=$U$2,0,IFERROR(VLOOKUP(N10,Stats!$B$24:$B$27,1,FALSE),"Company")) -> 0 | Z10: =COUNTIF(U10:Y10,$U$4) -> 0 | AB10: Character (Mage-lord) | AC10: =IFERROR(VLOOKUP($AB10,format!$C$5:$Q$30,1,FALSE),0) -> 0 | AD10: =IFERROR(VLOOKUP($AB10,format!$C$5:$Q$30,15,FALSE),0) -> 0 | AE10: =IFERROR(VLOOKUP($AB10,format!$L$5:$Q$30,6,FALSE),0) -> 0 | AF10: =IFERROR(VLOOKUP($AB10,format!$M$5:$Q$30,5,FALSE),0) -> 0 | AG10: =IFERROR(VLOOKUP($AB10,$N$5:$Q$29,4,FALSE),0) -> 0 | AH10: =SUM(AD10:AG10) -> 0 | AI10: =COUNTIF(format!$L$5:$N$30,Builder!AB10) -> 0 | AJ10: =IF(AI10>AH10,AI10,AH10) -> 0 | AM10: =BH10+BR10+CB10+CL10+CV10+DG10 -> 0 | AN10: =BI10+BS10+CC10+CM10+CW10+DH10 -> 0 | AO10: =BJ10+BT10+CD10+CN10+CX10+DI10 -> 0 | AP10: =IF(MAX(BK10,BU10,CE10,CO10,CY10,DJ10)>1,MAX(BK10,BU10,CE10,CO10,CY10,DJ10),BK10+BU10+CE10+CO10+CY10+DJ10) -> 0 | AQ10: =IF(AND(C8="Ordnance battery",(OR(K8="Shooting (mixed)",L8="Shooting (mixed)",M8="Shooting (mixed)",N8="Shooting (mixed)"))),1,IF(MAX(BL10,BV10,CF10,CP10,CZ10,DK10)>1,MAX(BL10,BV10,CF10,CP10,CZ10,DK10),BL10+BV10+CF10+CP10+CZ10+DK10)) -> 0 | AR10: =BM10+BW10+CG10+CQ10+DA10+DL10 -> 0 | AS10: =BN10+BX10+CH10+CR10+DB10+DM10 -> 0 | BC10: =IFERROR(VLOOKUP($O8,Relics,BC$2,FALSE),0) -> 0 | BD10: =IFERROR(VLOOKUP($O8,Relics,BD$2,FALSE),0) -> 0 | BG10: =IFERROR(VLOOKUP($C8,stats,BG$2,FALSE),0) -> 0 | BH10: =IFERROR(VLOOKUP($C8,stats,BH$2,FALSE),0) -> 0 | BI10: =IFERROR(VLOOKUP($C8,stats,BI$2,FALSE),0) -> 0 | BJ10: =IFERROR(VLOOKUP($C8,stats,BJ$2,FALSE),0) -> 0 | BK10: =IFERROR(VLOOKUP($C8,stats,BK$2,FALSE),0) -> 0 | BL10: =IFERROR(VLOOKUP($C8,stats,BL$2,FALSE),0) -> 0 | BM10: =IFERROR(VLOOKUP($C8,stats,BM$2,FALSE),0) -> 0 | BN10: =IFERROR(VLOOKUP($C8,stats,BN$2,FALSE),0) -> 0 | BO10: =IFERROR(VLOOKUP($C8,stats,BO$2,FALSE),0) -> 0 | BQ10: =IFERROR(VLOOKUP($K8,traits,BQ$2,FALSE),0) -> 0 | BR10: =IFERROR(VLOOKUP($K8,traits,BR$2,FALSE),0) -> 0 | BS10: =IFERROR(VLOOKUP($K8,traits,BS$2,FALSE),0) -> 0 | BT10: =IFERROR(VLOOKUP($K8,traits,BT$2,FALSE),0) -> 0 | BU10: =IFERROR(VLOOKUP($K8,traits,BU$2,FALSE),0) -> 0 | BV10: =IFERROR(VLOOKUP($K8,traits,BV$2,FALSE),0) -> 0 | BW10: =IFERROR(VLOOKUP($K8,traits,BW$2,FALSE),0) -> 0 | BX10: =IFERROR(VLOOKUP($K8,traits,BX$2,FALSE),0) -> 0 | BY10: =IFERROR(VLOOKUP($K8,traits,BY$2,FALSE),0) -> 0 | CA10: =IFERROR(VLOOKUP($L8,traits,CA$2,FALSE),0) -> 0 | CB10: =IFERROR(VLOOKUP($L8,traits,CB$2,FALSE),0) -> 0 | CC10: =IFERROR(VLOOKUP($L8,traits,CC$2,FALSE),0) -> 0 | CD10: =IFERROR(VLOOKUP($L8,traits,CD$2,FALSE),0) -> 0 | CE10: =IFERROR(VLOOKUP($L8,traits,CE$2,FALSE),0) -> 0 | CF10: =IFERROR(VLOOKUP($L8,traits,CF$2,FALSE),0) -> 0 | CG10: =IFERROR(VLOOKUP($L8,traits,CG$2,FALSE),0) -> 0 | CH10: =IFERROR(VLOOKUP($L8,traits,CH$2,FALSE),0) -> 0 | CI10: =IFERROR(VLOOKUP($L8,traits,CI$2,FALSE),0) -> 0 | CK10: =IFERROR(VLOOKUP($M8,traits,CK$2,FALSE),0) -> 0 | CL10: =IFERROR(VLOOKUP($M8,traits,CL$2,FALSE),0) -> 0 | CM10: =IFERROR(VLOOKUP($M8,traits,CM$2,FALSE),0) -> 0 | CN10: =IFERROR(VLOOKUP($M8,traits,CN$2,FALSE),0) -> 0 | CO10: =IFERROR(VLOOKUP($M8,traits,CO$2,FALSE),0) -> 0 | CP10: =IFERROR(VLOOKUP($M8,traits,CP$2,FALSE),0) -> 0 | CQ10: =IFERROR(VLOOKUP($M8,traits,CQ$2,FALSE),0) -> 0 | CR10: =IFERROR(VLOOKUP($M8,traits,CR$2,FALSE),0) -> 0 | CS10: =IFERROR(VLOOKUP($M8,traits,CS$2,FALSE),0) -> 0 | CU10: =IFERROR(VLOOKUP($N8,traits,CU$2,FALSE),0) -> 0 | CV10: =IFERROR(VLOOKUP($N8,traits,CV$2,FALSE),0) -> 0 | CW10: =IFERROR(VLOOKUP($N8,traits,CW$2,FALSE),0) -> 0 | CX10: =IFERROR(VLOOKUP($N8,traits,CX$2,FALSE),0) -> 0 | CY10: =IFERROR(VLOOKUP($N8,traits,CY$2,FALSE),0) -> 0 | CZ10: =IFERROR(VLOOKUP($N8,traits,CZ$2,FALSE),0) -> 0 | DA10: =IFERROR(VLOOKUP($N8,traits,DA$2,FALSE),0) -> 0 | DB10: =IFERROR(VLOOKUP($N8,traits,DB$2,FALSE),0) -> 0 | DC10: =IFERROR(VLOOKUP($N8,traits,DC$2,FALSE),0) -> 0 | DF10: =IFERROR(VLOOKUP($O8,Relics,DF$2,FALSE),0) -> 0 | DG10: =IFERROR(VLOOKUP($O8,Relics,DG$2,FALSE),0) -> 0 | DH10: =IFERROR(VLOOKUP($O8,Relics,DH$2,FALSE),0) -> 0 | DI10: =IFERROR(VLOOKUP($O8,Relics,DI$2,FALSE),0) -> 0 | DJ10: =IFERROR(VLOOKUP($O8,Relics,DJ$2,FALSE),0) -> 0 | DK10: =IFERROR(VLOOKUP($O8,Relics,DK$2,FALSE),0) -> 0 | DL10: =IFERROR(VLOOKUP($O8,Relics,DL$2,FALSE),0) -> 0 | DM10: =IFERROR(VLOOKUP($O8,Relics,DM$2,FALSE),0) -> 0 | DN10: =IFERROR(VLOOKUP($O8,Relics,DN$2,FALSE),0) -> 0
A11: 7 | D11: =AM13 -> 0 | E11: =AN13 -> 0 | F11: =AO13 -> 0 | G11: =AP13 -> 0 | H11: =AQ13 -> 0 | I11: =AR13 -> 0 | J11: =AS13 -> 0 | P11: =BO13+BY13+CI13+CS13+DC13+BD13 -> 0 | R11: =Q11*P11 -> 0 | U11: =IF(C11=$U$2,0,IFERROR(VLOOKUP($C11,Stats!$B$4:$B$8,1,FALSE),"Company")) -> 0 | V11: =IF(C11=$U$2,0,IFERROR(VLOOKUP(K11,Stats!$B$24:$B$27,1,FALSE),"Company")) -> 0 | W11: =IF(D11=$U$2,0,IFERROR(VLOOKUP(L11,Stats!$B$24:$B$27,1,FALSE),"Company")) -> 0 | X11: =IF(E11=$U$2,0,IFERROR(VLOOKUP(M11,Stats!$B$24:$B$27,1,FALSE),"Company")) -> 0 | Y11: =IF(F11=$U$2,0,IFERROR(VLOOKUP(N11,Stats!$B$24:$B$27,1,FALSE),"Company")) -> 0 | Z11: =COUNTIF(U11:Y11,$U$4) -> 0 | AB11: Character (Captain) | AC11: =IFERROR(VLOOKUP($AB11,format!$C$5:$Q$30,1,FALSE),0) -> 0 | AD11: =IFERROR(VLOOKUP($AB11,format!$C$5:$Q$30,15,FALSE),0) -> 0 | AE11: =IFERROR(VLOOKUP($AB11,format!$L$5:$Q$30,6,FALSE),0) -> 0 | AF11: =IFERROR(VLOOKUP($AB11,format!$M$5:$Q$30,5,FALSE),0) -> 0 | AG11: =IFERROR(VLOOKUP($AB11,$N$5:$Q$29,4,FALSE),0) -> 0 | AH11: =SUM(AD11:AG11) -> 0 | AI11: =COUNTIF(format!$L$5:$N$30,Builder!AB11) -> 0 | AJ11: =IF(AI11>AH11,AI11,AH11) -> 0 | AM11: =BH11+BR11+CB11+CL11+CV11+DG11 -> 0 | AN11: =BI11+BS11+CC11+CM11+CW11+DH11 -> 0 | AO11: =BJ11+BT11+CD11+CN11+CX11+DI11 -> 0 | AP11: =IF(MAX(BK11,BU11,CE11,CO11,CY11,DJ11)>1,MAX(BK11,BU11,CE11,CO11,CY11,DJ11),BK11+BU11+CE11+CO11+CY11+DJ11) -> 0 | AQ11: =IF(AND(C9="Ordnance battery",(OR(K9="Shooting (mixed)",L9="Shooting (mixed)",M9="Shooting (mixed)",N9="Shooting (mixed)"))),1,IF(MAX(BL11,BV11,CF11,CP11,CZ11,DK11)>1,MAX(BL11,BV11,CF11,CP11,CZ11,DK11),BL11+BV11+CF11+CP11+CZ11+DK11)) -> 0 | AR11: =BM11+BW11+CG11+CQ11+DA11+DL11 -> 0 | AS11: =BN11+BX11+CH11+CR11+DB11+DM11 -> 0 | BC11: =IFERROR(VLOOKUP($O9,Relics,BC$2,FALSE),0) -> 0 | BD11: =IFERROR(VLOOKUP($O9,Relics,BD$2,FALSE),0) -> 0 | BG11: =IFERROR(VLOOKUP($C9,stats,BG$2,FALSE),0) -> 0 | BH11: =IFERROR(VLOOKUP($C9,stats,BH$2,FALSE),0) -> 0 | BI11: =IFERROR(VLOOKUP($C9,stats,BI$2,FALSE),0) -> 0 | BJ11: =IFERROR(VLOOKUP($C9,stats,BJ$2,FALSE),0) -> 0 | BK11: =IFERROR(VLOOKUP($C9,stats,BK$2,FALSE),0) -> 0 | BL11: =IFERROR(VLOOKUP($C9,stats,BL$2,FALSE),0) -> 0 | BM11: =IFERROR(VLOOKUP($C9,stats,BM$2,FALSE),0) -> 0 | BN11: =IFERROR(VLOOKUP($C9,stats,BN$2,FALSE),0) -> 0 | BO11: =IFERROR(VLOOKUP($C9,stats,BO$2,FALSE),0) -> 0 | BQ11: =IFERROR(VLOOKUP($K9,traits,BQ$2,FALSE),0) -> 0 | BR11: =IFERROR(VLOOKUP($K9,traits,BR$2,FALSE),0) -> 0 | BS11: =IFERROR(VLOOKUP($K9,traits,BS$2,FALSE),0) -> 0 | BT11: =IFERROR(VLOOKUP($K9,traits,BT$2,FALSE),0) -> 0 | BU11: =IFERROR(VLOOKUP($K9,traits,BU$2,FALSE),0) -> 0 | BV11: =IFERROR(VLOOKUP($K9,traits,BV$2,FALSE),0) -> 0 | BW11: =IFERROR(VLOOKUP($K9,traits,BW$2,FALSE),0) -> 0 | BX11: =IFERROR(VLOOKUP($K9,traits,BX$2,FALSE),0) -> 0 | BY11: =IFERROR(VLOOKUP($K9,traits,BY$2,FALSE),0) -> 0 | CA11: =IFERROR(VLOOKUP($L9,traits,CA$2,FALSE),0) -> 0 | CB11: =IFERROR(VLOOKUP($L9,traits,CB$2,FALSE),0) -> 0 | CC11: =IFERROR(VLOOKUP($L9,traits,CC$2,FALSE),0) -> 0 | CD11: =IFERROR(VLOOKUP($L9,traits,CD$2,FALSE),0) -> 0 | CE11: =IFERROR(VLOOKUP($L9,traits,CE$2,FALSE),0) -> 0 | CF11: =IFERROR(VLOOKUP($L9,traits,CF$2,FALSE),0) -> 0 | CG11: =IFERROR(VLOOKUP($L9,traits,CG$2,FALSE),0) -> 0 | CH11: =IFERROR(VLOOKUP($L9,traits,CH$2,FALSE),0) -> 0 | CI11: =IFERROR(VLOOKUP($L9,traits,CI$2,FALSE),0) -> 0 | CK11: =IFERROR(VLOOKUP($M9,traits,CK$2,FALSE),0) -> 0 | CL11: =IFERROR(VLOOKUP($M9,traits,CL$2,FALSE),0) -> 0 | CM11: =IFERROR(VLOOKUP($M9,traits,CM$2,FALSE),0) -> 0 | CN11: =IFERROR(VLOOKUP($M9,traits,CN$2,FALSE),0) -> 0 | CO11: =IFERROR(VLOOKUP($M9,traits,CO$2,FALSE),0) -> 0 | CP11: =IFERROR(VLOOKUP($M9,traits,CP$2,FALSE),0) -> 0 | CQ11: =IFERROR(VLOOKUP($M9,traits,CQ$2,FALSE),0) -> 0 | CR11: =IFERROR(VLOOKUP($M9,traits,CR$2,FALSE),0) -> 0 | CS11: =IFERROR(VLOOKUP($M9,traits,CS$2,FALSE),0) -> 0 | CU11: =IFERROR(VLOOKUP($N9,traits,CU$2,FALSE),0) -> 0 | CV11: =IFERROR(VLOOKUP($N9,traits,CV$2,FALSE),0) -> 0 | CW11: =IFERROR(VLOOKUP($N9,traits,CW$2,FALSE),0) -> 0 | CX11: =IFERROR(VLOOKUP($N9,traits,CX$2,FALSE),0) -> 0 | CY11: =IFERROR(VLOOKUP($N9,traits,CY$2,FALSE),0) -> 0 | CZ11: =IFERROR(VLOOKUP($N9,traits,CZ$2,FALSE),0) -> 0 | DA11: =IFERROR(VLOOKUP($N9,traits,DA$2,FALSE),0) -> 0 | DB11: =IFERROR(VLOOKUP($N9,traits,DB$2,FALSE),0) -> 0 | DC11: =IFERROR(VLOOKUP($N9,traits,DC$2,FALSE),0) -> 0 | DF11: =IFERROR(VLOOKUP($O9,Relics,DF$2,FALSE),0) -> 0 | DG11: =IFERROR(VLOOKUP($O9,Relics,DG$2,FALSE),0) -> 0 | DH11: =IFERROR(VLOOKUP($O9,Relics,DH$2,FALSE),0) -> 0 | DI11: =IFERROR(VLOOKUP($O9,Relics,DI$2,FALSE),0) -> 0 | DJ11: =IFERROR(VLOOKUP($O9,Relics,DJ$2,FALSE),0) -> 0 | DK11: =IFERROR(VLOOKUP($O9,Relics,DK$2,FALSE),0) -> 0 | DL11: =IFERROR(VLOOKUP($O9,Relics,DL$2,FALSE),0) -> 0 | DM11: =IFERROR(VLOOKUP($O9,Relics,DM$2,FALSE),0) -> 0 | DN11: =IFERROR(VLOOKUP($O9,Relics,DN$2,FALSE),0) -> 0
A12: 8 | D12: =AM14 -> 0 | E12: =AN14 -> 0 | F12: =AO14 -> 0 | G12: =AP14 -> 0 | H12: =AQ14 -> 0 | I12: =AR14 -> 0 | J12: =AS14 -> 0 | P12: =BO14+BY14+CI14+CS14+DC14+BD14 -> 0 | R12: =Q12*P12 -> 0 | U12: =IF(C12=$U$2,0,IFERROR(VLOOKUP($C12,Stats!$B$4:$B$8,1,FALSE),"Company")) -> 0 | V12: =IF(C12=$U$2,0,IFERROR(VLOOKUP(K12,Stats!$B$24:$B$27,1,FALSE),"Company")) -> 0 | W12: =IF(D12=$U$2,0,IFERROR(VLOOKUP(L12,Stats!$B$24:$B$27,1,FALSE),"Company")) -> 0 | X12: =IF(E12=$U$2,0,IFERROR(VLOOKUP(M12,Stats!$B$24:$B$27,1,FALSE),"Company")) -> 0 | Y12: =IF(F12=$U$2,0,IFERROR(VLOOKUP(N12,Stats!$B$24:$B$27,1,FALSE),"Company")) -> 0 | Z12: =COUNTIF(U12:Y12,$U$4) -> 0 | AB12: Character (Magic-user) | AC12: =IFERROR(VLOOKUP($AB12,format!$C$5:$Q$30,1,FALSE),0) -> 0 | AD12: =IFERROR(VLOOKUP($AB12,format!$C$5:$Q$30,15,FALSE),0) -> 0 | AE12: =IFERROR(VLOOKUP($AB12,format!$L$5:$Q$30,6,FALSE),0) -> 0 | AF12: =IFERROR(VLOOKUP($AB12,format!$M$5:$Q$30,5,FALSE),0) -> 0 | AG12: =IFERROR(VLOOKUP($AB12,$N$5:$Q$29,4,FALSE),0) -> 0 | AH12: =SUM(AD12:AG12) -> 0 | AI12: =COUNTIF(format!$L$5:$N$30,Builder!AB12) -> 0 | AJ12: =IF(AI12>AH12,AI12,AH12) -> 0 | AM12: =BH12+BR12+CB12+CL12+CV12+DG12 -> 0 | AN12: =BI12+BS12+CC12+CM12+CW12+DH12 -> 0 | AO12: =BJ12+BT12+CD12+CN12+CX12+DI12 -> 0 | AP12: =IF(MAX(BK12,BU12,CE12,CO12,CY12,DJ12)>1,MAX(BK12,BU12,CE12,CO12,CY12,DJ12),BK12+BU12+CE12+CO12+CY12+DJ12) -> 0 | AQ12: =IF(AND(C10="Ordnance battery",(OR(K10="Shooting (mixed)",L10="Shooting (mixed)",M10="Shooting (mixed)",N10="Shooting (mixed)"))),1,IF(MAX(BL12,BV12,CF12,CP12,CZ12,DK12)>1,MAX(BL12,BV12,CF12,CP12,CZ12,DK12),BL12+BV12+CF12+CP12+CZ12+DK12)) -> 0 | AR12: =BM12+BW12+CG12+CQ12+DA12+DL12 -> 0 | AS12: =BN12+BX12+CH12+CR12+DB12+DM12 -> 0 | BC12: =IFERROR(VLOOKUP($O10,Relics,BC$2,FALSE),0) -> 0 | BD12: =IFERROR(VLOOKUP($O10,Relics,BD$2,FALSE),0) -> 0 | BG12: =IFERROR(VLOOKUP($C10,stats,BG$2,FALSE),0) -> 0 | BH12: =IFERROR(VLOOKUP($C10,stats,BH$2,FALSE),0) -> 0 | BI12: =IFERROR(VLOOKUP($C10,stats,BI$2,FALSE),0) -> 0 | BJ12: =IFERROR(VLOOKUP($C10,stats,BJ$2,FALSE),0) -> 0 | BK12: =IFERROR(VLOOKUP($C10,stats,BK$2,FALSE),0) -> 0 | BL12: =IFERROR(VLOOKUP($C10,stats,BL$2,FALSE),0) -> 0 | BM12: =IFERROR(VLOOKUP($C10,stats,BM$2,FALSE),0) -> 0 | BN12: =IFERROR(VLOOKUP($C10,stats,BN$2,FALSE),0) -> 0 | BO12: =IFERROR(VLOOKUP($C10,stats,BO$2,FALSE),0) -> 0 | BQ12: =IFERROR(VLOOKUP($K10,traits,BQ$2,FALSE),0) -> 0 | BR12: =IFERROR(VLOOKUP($K10,traits,BR$2,FALSE),0) -> 0 | BS12: =IFERROR(VLOOKUP($K10,traits,BS$2,FALSE),0) -> 0 | BT12: =IFERROR(VLOOKUP($K10,traits,BT$2,FALSE),0) -> 0 | BU12: =IFERROR(VLOOKUP($K10,traits,BU$2,FALSE),0) -> 0 | BV12: =IFERROR(VLOOKUP($K10,traits,BV$2,FALSE),0) -> 0 | BW12: =IFERROR(VLOOKUP($K10,traits,BW$2,FALSE),0) -> 0 | BX12: =IFERROR(VLOOKUP($K10,traits,BX$2,FALSE),0) -> 0 | BY12: =IFERROR(VLOOKUP($K10,traits,BY$2,FALSE),0) -> 0 | CA12: =IFERROR(VLOOKUP($L10,traits,CA$2,FALSE),0) -> 0 | CB12: =IFERROR(VLOOKUP($L10,traits,CB$2,FALSE),0) -> 0 | CC12: =IFERROR(VLOOKUP($L10,traits,CC$2,FALSE),0) -> 0 | CD12: =IFERROR(VLOOKUP($L10,traits,CD$2,FALSE),0) -> 0 | CE12: =IFERROR(VLOOKUP($L10,traits,CE$2,FALSE),0) -> 0 | CF12: =IFERROR(VLOOKUP($L10,traits,CF$2,FALSE),0) -> 0 | CG12: =IFERROR(VLOOKUP($L10,traits,CG$2,FALSE),0) -> 0 | CH12: =IFERROR(VLOOKUP($L10,traits,CH$2,FALSE),0) -> 0 | CI12: =IFERROR(VLOOKUP($L10,traits,CI$2,FALSE),0) -> 0 | CK12: =IFERROR(VLOOKUP($M10,traits,CK$2,FALSE),0) -> 0 | CL12: =IFERROR(VLOOKUP($M10,traits,CL$2,FALSE),0) -> 0 | CM12: =IFERROR(VLOOKUP($M10,traits,CM$2,FALSE),0) -> 0 | CN12: =IFERROR(VLOOKUP($M10,traits,CN$2,FALSE),0) -> 0 | CO12: =IFERROR(VLOOKUP($M10,traits,CO$2,FALSE),0) -> 0 | CP12: =IFERROR(VLOOKUP($M10,traits,CP$2,FALSE),0) -> 0 | CQ12: =IFERROR(VLOOKUP($M10,traits,CQ$2,FALSE),0) -> 0 | CR12: =IFERROR(VLOOKUP($M10,traits,CR$2,FALSE),0) -> 0 | CS12: =IFERROR(VLOOKUP($M10,traits,CS$2,FALSE),0) -> 0 | CU12: =IFERROR(VLOOKUP($N10,traits,CU$2,FALSE),0) -> 0 | CV12: =IFERROR(VLOOKUP($N10,traits,CV$2,FALSE),0) -> 0 | CW12: =IFERROR(VLOOKUP($N10,traits,CW$2,FALSE),0) -> 0 | CX12: =IFERROR(VLOOKUP($N10,traits,CX$2,FALSE),0) -> 0 | CY12: =IFERROR(VLOOKUP($N10,traits,CY$2,FALSE),0) -> 0 | CZ12: =IFERROR(VLOOKUP($N10,traits,CZ$2,FALSE),0) -> 0 | DA12: =IFERROR(VLOOKUP($N10,traits,DA$2,FALSE),0) -> 0 | DB12: =IFERROR(VLOOKUP($N10,traits,DB$2,FALSE),0) -> 0 | DC12: =IFERROR(VLOOKUP($N10,traits,DC$2,FALSE),0) -> 0 | DF12: =IFERROR(VLOOKUP($O10,Relics,DF$2,FALSE),0) -> 0 | DG12: =IFERROR(VLOOKUP($O10,Relics,DG$2,FALSE),0) -> 0 | DH12: =IFERROR(VLOOKUP($O10,Relics,DH$2,FALSE),0) -> 0 | DI12: =IFERROR(VLOOKUP($O10,Relics,DI$2,FALSE),0) -> 0 | DJ12: =IFERROR(VLOOKUP($O10,Relics,DJ$2,FALSE),0) -> 0 | DK12: =IFERROR(VLOOKUP($O10,Relics,DK$2,FALSE),0) -> 0 | DL12: =IFERROR(VLOOKUP($O10,Relics,DL$2,FALSE),0) -> 0 | DM12: =IFERROR(VLOOKUP($O10,Relics,DM$2,FALSE),0) -> 0 | DN12: =IFERROR(VLOOKUP($O10,Relics,DN$2,FALSE),0) -> 0
A13: 9 | D13: =AM15 -> 0 | E13: =AN15 -> 0 | F13: =AO15 -> 0 | G13: =AP15 -> 0 | H13: =AQ15 -> 0 | I13: =AR15 -> 0 | J13: =AS15 -> 0 | P13: =BO15+BY15+CI15+CS15+DC15+BD15 -> 0 | R13: =Q13*P13 -> 0 | U13: =IF(C13=$U$2,0,IFERROR(VLOOKUP($C13,Stats!$B$4:$B$8,1,FALSE),"Company")) -> 0 | V13: =IF(C13=$U$2,0,IFERROR(VLOOKUP(K13,Stats!$B$24:$B$27,1,FALSE),"Company")) -> 0 | W13: =IF(D13=$U$2,0,IFERROR(VLOOKUP(L13,Stats!$B$24:$B$27,1,FALSE),"Company")) -> 0 | X13: =IF(E13=$U$2,0,IFERROR(VLOOKUP(M13,Stats!$B$24:$B$27,1,FALSE),"Company")) -> 0 | Y13: =IF(F13=$U$2,0,IFERROR(VLOOKUP(N13,Stats!$B$24:$B$27,1,FALSE),"Company")) -> 0 | Z13: =COUNTIF(U13:Y13,$U$4) -> 0 | AD13: allowed | AE13: total | AM13: =BH13+BR13+CB13+CL13+CV13+DG13 -> 0 | AN13: =BI13+BS13+CC13+CM13+CW13+DH13 -> 0 | AO13: =BJ13+BT13+CD13+CN13+CX13+DI13 -> 0 | AP13: =IF(MAX(BK13,BU13,CE13,CO13,CY13,DJ13)>1,MAX(BK13,BU13,CE13,CO13,CY13,DJ13),BK13+BU13+CE13+CO13+CY13+DJ13) -> 0 | AQ13: =IF(AND(C11="Ordnance battery",(OR(K11="Shooting (mixed)",L11="Shooting (mixed)",M11="Shooting (mixed)",N11="Shooting (mixed)"))),1,IF(MAX(BL13,BV13,CF13,CP13,CZ13,DK13)>1,MAX(BL13,BV13,CF13,CP13,CZ13,DK13),BL13+BV13+CF13+CP13+CZ13+DK13)) -> 0 | AR13: =BM13+BW13+CG13+CQ13+DA13+DL13 -> 0 | AS13: =BN13+BX13+CH13+CR13+DB13+DM13 -> 0 | BC13: =IFERROR(VLOOKUP($O11,Relics,BC$2,FALSE),0) -> 0 | BD13: =IFERROR(VLOOKUP($O11,Relics,BD$2,FALSE),0) -> 0 | BG13: =IFERROR(VLOOKUP($C11,stats,BG$2,FALSE),0) -> 0 | BH13: =IFERROR(VLOOKUP($C11,stats,BH$2,FALSE),0) -> 0 | BI13: =IFERROR(VLOOKUP($C11,stats,BI$2,FALSE),0) -> 0 | BJ13: =IFERROR(VLOOKUP($C11,stats,BJ$2,FALSE),0) -> 0 | BK13: =IFERROR(VLOOKUP($C11,stats,BK$2,FALSE),0) -> 0 | BL13: =IFERROR(VLOOKUP($C11,stats,BL$2,FALSE),0) -> 0 | BM13: =IFERROR(VLOOKUP($C11,stats,BM$2,FALSE),0) -> 0 | BN13: =IFERROR(VLOOKUP($C11,stats,BN$2,FALSE),0) -> 0 | BO13: =IFERROR(VLOOKUP($C11,stats,BO$2,FALSE),0) -> 0 | BQ13: =IFERROR(VLOOKUP($K11,traits,BQ$2,FALSE),0) -> 0 | BR13: =IFERROR(VLOOKUP($K11,traits,BR$2,FALSE),0) -> 0 | BS13: =IFERROR(VLOOKUP($K11,traits,BS$2,FALSE),0) -> 0 | BT13: =IFERROR(VLOOKUP($K11,traits,BT$2,FALSE),0) -> 0 | BU13: =IFERROR(VLOOKUP($K11,traits,BU$2,FALSE),0) -> 0 | BV13: =IFERROR(VLOOKUP($K11,traits,BV$2,FALSE),0) -> 0 | BW13: =IFERROR(VLOOKUP($K11,traits,BW$2,FALSE),0) -> 0 | BX13: =IFERROR(VLOOKUP($K11,traits,BX$2,FALSE),0) -> 0 | BY13: =IFERROR(VLOOKUP($K11,traits,BY$2,FALSE),0) -> 0 | CA13: =IFERROR(VLOOKUP($L11,traits,CA$2,FALSE),0) -> 0 | CB13: =IFERROR(VLOOKUP($L11,traits,CB$2,FALSE),0) -> 0 | CC13: =IFERROR(VLOOKUP($L11,traits,CC$2,FALSE),0) -> 0 | CD13: =IFERROR(VLOOKUP($L11,traits,CD$2,FALSE),0) -> 0 | CE13: =IFERROR(VLOOKUP($L11,traits,CE$2,FALSE),0) -> 0 | CF13: =IFERROR(VLOOKUP($L11,traits,CF$2,FALSE),0) -> 0 | CG13: =IFERROR(VLOOKUP($L11,traits,CG$2,FALSE),0) -> 0 | CH13: =IFERROR(VLOOKUP($L11,traits,CH$2,FALSE),0) -> 0 | CI13: =IFERROR(VLOOKUP($L11,traits,CI$2,FALSE),0) -> 0 | CK13: =IFERROR(VLOOKUP($M11,traits,CK$2,FALSE),0) -> 0 | CL13: =IFERROR(VLOOKUP($M11,traits,CL$2,FALSE),0) -> 0 | CM13: =IFERROR(VLOOKUP($M11,traits,CM$2,FALSE),0) -> 0 | CN13: =IFERROR(VLOOKUP($M11,traits,CN$2,FALSE),0) -> 0 | CO13: =IFERROR(VLOOKUP($M11,traits,CO$2,FALSE),0) -> 0 | CP13: =IFERROR(VLOOKUP($M11,traits,CP$2,FALSE),0) -> 0 | CQ13: =IFERROR(VLOOKUP($M11,traits,CQ$2,FALSE),0) -> 0 | CR13: =IFERROR(VLOOKUP($M11,traits,CR$2,FALSE),0) -> 0 | CS13: =IFERROR(VLOOKUP($M11,traits,CS$2,FALSE),0) -> 0 | CU13: =IFERROR(VLOOKUP($N11,traits,CU$2,FALSE),0) -> 0 | CV13: =IFERROR(VLOOKUP($N11,traits,CV$2,FALSE),0) -> 0 | CW13: =IFERROR(VLOOKUP($N11,traits,CW$2,FALSE),0) -> 0 | CX13: =IFERROR(VLOOKUP($N11,traits,CX$2,FALSE),0) -> 0 | CY13: =IFERROR(VLOOKUP($N11,traits,CY$2,FALSE),0) -> 0 | CZ13: =IFERROR(VLOOKUP($N11,traits,CZ$2,FALSE),0) -> 0 | DA13: =IFERROR(VLOOKUP($N11,traits,DA$2,FALSE),0) -> 0 | DB13: =IFERROR(VLOOKUP($N11,traits,DB$2,FALSE),0) -> 0 | DC13: =IFERROR(VLOOKUP($N11,traits,DC$2,FALSE),0) -> 0 | DF13: =IFERROR(VLOOKUP($O11,Relics,DF$2,FALSE),0) -> 0 | DG13: =IFERROR(VLOOKUP($O11,Relics,DG$2,FALSE),0) -> 0 | DH13: =IFERROR(VLOOKUP($O11,Relics,DH$2,FALSE),0) -> 0 | DI13: =IFERROR(VLOOKUP($O11,Relics,DI$2,FALSE),0) -> 0 | DJ13: =IFERROR(VLOOKUP($O11,Relics,DJ$2,FALSE),0) -> 0 | DK13: =IFERROR(VLOOKUP($O11,Relics,DK$2,FALSE),0) -> 0 | DL13: =IFERROR(VLOOKUP($O11,Relics,DL$2,FALSE),0) -> 0 | DM13: =IFERROR(VLOOKUP($O11,Relics,DM$2,FALSE),0) -> 0 | DN13: =IFERROR(VLOOKUP($O11,Relics,DN$2,FALSE),0) -> 0
A14: 10 | D14: =AM16 -> 0 | E14: =AN16 -> 0 | F14: =AO16 -> 0 | G14: =AP16 -> 0 | H14: =AQ16 -> 0 | I14: =AR16 -> 0 | J14: =AS16 -> 0 | P14: =BO16+BY16+CI16+CS16+DC16+BD16 -> 0 | R14: =Q14*P14 -> 0 | U14: =IF(C14=$U$2,0,IFERROR(VLOOKUP($C14,Stats!$B$4:$B$8,1,FALSE),"Company")) -> 0 | V14: =IF(C14=$U$2,0,IFERROR(VLOOKUP(K14,Stats!$B$24:$B$27,1,FALSE),"Company")) -> 0 | W14: =IF(D14=$U$2,0,IFERROR(VLOOKUP(L14,Stats!$B$24:$B$27,1,FALSE),"Company")) -> 0 | X14: =IF(E14=$U$2,0,IFERROR(VLOOKUP(M14,Stats!$B$24:$B$27,1,FALSE),"Company")) -> 0 | Y14: =IF(F14=$U$2,0,IFERROR(VLOOKUP(N14,Stats!$B$24:$B$27,1,FALSE),"Company")) -> 0 | Z14: =COUNTIF(U14:Y14,$U$4) -> 0 | AC14: allowed/500 | AD14: =Stats!T2 -> 0 | AM14: =BH14+BR14+CB14+CL14+CV14+DG14 -> 0 | AN14: =BI14+BS14+CC14+CM14+CW14+DH14 -> 0 | AO14: =BJ14+BT14+CD14+CN14+CX14+DI14 -> 0 | AP14: =IF(MAX(BK14,BU14,CE14,CO14,CY14,DJ14)>1,MAX(BK14,BU14,CE14,CO14,CY14,DJ14),BK14+BU14+CE14+CO14+CY14+DJ14) -> 0 | AQ14: =IF(AND(C12="Ordnance battery",(OR(K12="Shooting (mixed)",L12="Shooting (mixed)",M12="Shooting (mixed)",N12="Shooting (mixed)"))),1,IF(MAX(BL14,BV14,CF14,CP14,CZ14,DK14)>1,MAX(BL14,BV14,CF14,CP14,CZ14,DK14),BL14+BV14+CF14+CP14+CZ14+DK14)) -> 0 | AR14: =BM14+BW14+CG14+CQ14+DA14+DL14 -> 0 | AS14: =BN14+BX14+CH14+CR14+DB14+DM14 -> 0 | BC14: =IFERROR(VLOOKUP($O12,Relics,BC$2,FALSE),0) -> 0 | BD14: =IFERROR(VLOOKUP($O12,Relics,BD$2,FALSE),0) -> 0 | BG14: =IFERROR(VLOOKUP($C12,stats,BG$2,FALSE),0) -> 0 | BH14: =IFERROR(VLOOKUP($C12,stats,BH$2,FALSE),0) -> 0 | BI14: =IFERROR(VLOOKUP($C12,stats,BI$2,FALSE),0) -> 0 | BJ14: =IFERROR(VLOOKUP($C12,stats,BJ$2,FALSE),0) -> 0 | BK14: =IFERROR(VLOOKUP($C12,stats,BK$2,FALSE),0) -> 0 | BL14: =IFERROR(VLOOKUP($C12,stats,BL$2,FALSE),0) -> 0 | BM14: =IFERROR(VLOOKUP($C12,stats,BM$2,FALSE),0) -> 0 | BN14: =IFERROR(VLOOKUP($C12,stats,BN$2,FALSE),0) -> 0 | BO14: =IFERROR(VLOOKUP($C12,stats,BO$2,FALSE),0) -> 0 | BQ14: =IFERROR(VLOOKUP($K12,traits,BQ$2,FALSE),0) -> 0 | BR14: =IFERROR(VLOOKUP($K12,traits,BR$2,FALSE),0) -> 0 | BS14: =IFERROR(VLOOKUP($K12,traits,BS$2,FALSE),0) -> 0 | BT14: =IFERROR(VLOOKUP($K12,traits,BT$2,FALSE),0) -> 0 | BU14: =IFERROR(VLOOKUP($K12,traits,BU$2,FALSE),0) -> 0 | BV14: =IFERROR(VLOOKUP($K12,traits,BV$2,FALSE),0) -> 0 | BW14: =IFERROR(VLOOKUP($K12,traits,BW$2,FALSE),0) -> 0 | BX14: =IFERROR(VLOOKUP($K12,traits,BX$2,FALSE),0) -> 0 | BY14: =IFERROR(VLOOKUP($K12,traits,BY$2,FALSE),0) -> 0 | CA14: =IFERROR(VLOOKUP($L12,traits,CA$2,FALSE),0) -> 0 | CB14: =IFERROR(VLOOKUP($L12,traits,CB$2,FALSE),0) -> 0 | CC14: =IFERROR(VLOOKUP($L12,traits,CC$2,FALSE),0) -> 0 | CD14: =IFERROR(VLOOKUP($L12,traits,CD$2,FALSE),0) -> 0 | CE14: =IFERROR(VLOOKUP($L12,traits,CE$2,FALSE),0) -> 0 | CF14: =IFERROR(VLOOKUP($L12,traits,CF$2,FALSE),0) -> 0 | CG14: =IFERROR(VLOOKUP($L12,traits,CG$2,FALSE),0) -> 0 | CH14: =IFERROR(VLOOKUP($L12,traits,CH$2,FALSE),0) -> 0 | CI14: =IFERROR(VLOOKUP($L12,traits,CI$2,FALSE),0) -> 0 | CK14: =IFERROR(VLOOKUP($M12,traits,CK$2,FALSE),0) -> 0 | CL14: =IFERROR(VLOOKUP($M12,traits,CL$2,FALSE),0) -> 0 | CM14: =IFERROR(VLOOKUP($M12,traits,CM$2,FALSE),0) -> 0 | CN14: =IFERROR(VLOOKUP($M12,traits,CN$2,FALSE),0) -> 0 | CO14: =IFERROR(VLOOKUP($M12,traits,CO$2,FALSE),0) -> 0 | CP14: =IFERROR(VLOOKUP($M12,traits,CP$2,FALSE),0) -> 0 | CQ14: =IFERROR(VLOOKUP($M12,traits,CQ$2,FALSE),0) -> 0 | CR14: =IFERROR(VLOOKUP($M12,traits,CR$2,FALSE),0) -> 0 | CS14: =IFERROR(VLOOKUP($M12,traits,CS$2,FALSE),0) -> 0 | CU14: =IFERROR(VLOOKUP($N12,traits,CU$2,FALSE),0) -> 0 | CV14: =IFERROR(VLOOKUP($N12,traits,CV$2,FALSE),0) -> 0 | CW14: =IFERROR(VLOOKUP($N12,traits,CW$2,FALSE),0) -> 0 | CX14: =IFERROR(VLOOKUP($N12,traits,CX$2,FALSE),0) -> 0 | CY14: =IFERROR(VLOOKUP($N12,traits,CY$2,FALSE),0) -> 0 | CZ14: =IFERROR(VLOOKUP($N12,traits,CZ$2,FALSE),0) -> 0 | DA14: =IFERROR(VLOOKUP($N12,traits,DA$2,FALSE),0) -> 0 | DB14: =IFERROR(VLOOKUP($N12,traits,DB$2,FALSE),0) -> 0 | DC14: =IFERROR(VLOOKUP($N12,traits,DC$2,FALSE),0) -> 0 | DF14: =IFERROR(VLOOKUP($O12,Relics,DF$2,FALSE),0) -> 0 | DG14: =IFERROR(VLOOKUP($O12,Relics,DG$2,FALSE),0) -> 0 | DH14: =IFERROR(VLOOKUP($O12,Relics,DH$2,FALSE),0) -> 0 | DI14: =IFERROR(VLOOKUP($O12,Relics,DI$2,FALSE),0) -> 0 | DJ14: =IFERROR(VLOOKUP($O12,Relics,DJ$2,FALSE),0) -> 0 | DK14: =IFERROR(VLOOKUP($O12,Relics,DK$2,FALSE),0) -> 0 | DL14: =IFERROR(VLOOKUP($O12,Relics,DL$2,FALSE),0) -> 0 | DM14: =IFERROR(VLOOKUP($O12,Relics,DM$2,FALSE),0) -> 0 | DN14: =IFERROR(VLOOKUP($O12,Relics,DN$2,FALSE),0) -> 0
A15: 11 | D15: =AM17 -> 0 | E15: =AN17 -> 0 | F15: =AO17 -> 0 | G15: =AP17 -> 0 | H15: =AQ17 -> 0 | I15: =AR17 -> 0 | J15: =AS17 -> 0 | P15: =BO17+BY17+CI17+CS17+DC17+BD17 -> 0 | R15: =Q15*P15 -> 0 | U15: =IF(C15=$U$2,0,IFERROR(VLOOKUP($C15,Stats!$B$4:$B$8,1,FALSE),"Company")) -> 0 | V15: =IF(C15=$U$2,0,IFERROR(VLOOKUP(K15,Stats!$B$24:$B$27,1,FALSE),"Company")) -> 0 | W15: =IF(D15=$U$2,0,IFERROR(VLOOKUP(L15,Stats!$B$24:$B$27,1,FALSE),"Company")) -> 0 | X15: =IF(E15=$U$2,0,IFERROR(VLOOKUP(M15,Stats!$B$24:$B$27,1,FALSE),"Company")) -> 0 | Y15: =IF(F15=$U$2,0,IFERROR(VLOOKUP(N15,Stats!$B$24:$B$27,1,FALSE),"Company")) -> 0 | Z15: =COUNTIF(U15:Y15,$U$4) -> 0 | AB15: Mage-lord/Warlord | AC15: =Stats!R4 -> 1 | AD15: =Stats!T4 -> 1 | AE15: =AJ4+AJ5+AJ9+AJ10 -> 0 | AM15: =BH15+BR15+CB15+CL15+CV15+DG15 -> 0 | AN15: =BI15+BS15+CC15+CM15+CW15+DH15 -> 0 | AO15: =BJ15+BT15+CD15+CN15+CX15+DI15 -> 0 | AP15: =IF(MAX(BK15,BU15,CE15,CO15,CY15,DJ15)>1,MAX(BK15,BU15,CE15,CO15,CY15,DJ15),BK15+BU15+CE15+CO15+CY15+DJ15) -> 0 | AQ15: =IF(AND(C13="Ordnance battery",(OR(K13="Shooting (mixed)",L13="Shooting (mixed)",M13="Shooting (mixed)",N13="Shooting (mixed)"))),1,IF(MAX(BL15,BV15,CF15,CP15,CZ15,DK15)>1,MAX(BL15,BV15,CF15,CP15,CZ15,DK15),BL15+BV15+CF15+CP15+CZ15+DK15)) -> 0 | AR15: =BM15+BW15+CG15+CQ15+DA15+DL15 -> 0 | AS15: =BN15+BX15+CH15+CR15+DB15+DM15 -> 0 | BC15: =IFERROR(VLOOKUP($O13,Relics,BC$2,FALSE),0) -> 0 | BD15: =IFERROR(VLOOKUP($O13,Relics,BD$2,FALSE),0) -> 0 | BG15: =IFERROR(VLOOKUP($C13,stats,BG$2,FALSE),0) -> 0 | BH15: =IFERROR(VLOOKUP($C13,stats,BH$2,FALSE),0) -> 0 | BI15: =IFERROR(VLOOKUP($C13,stats,BI$2,FALSE),0) -> 0 | BJ15: =IFERROR(VLOOKUP($C13,stats,BJ$2,FALSE),0) -> 0 | BK15: =IFERROR(VLOOKUP($C13,stats,BK$2,FALSE),0) -> 0 | BL15: =IFERROR(VLOOKUP($C13,stats,BL$2,FALSE),0) -> 0 | BM15: =IFERROR(VLOOKUP($C13,stats,BM$2,FALSE),0) -> 0 | BN15: =IFERROR(VLOOKUP($C13,stats,BN$2,FALSE),0) -> 0 | BO15: =IFERROR(VLOOKUP($C13,stats,BO$2,FALSE),0) -> 0 | BQ15: =IFERROR(VLOOKUP($K13,traits,BQ$2,FALSE),0) -> 0 | BR15: =IFERROR(VLOOKUP($K13,traits,BR$2,FALSE),0) -> 0 | BS15: =IFERROR(VLOOKUP($K13,traits,BS$2,FALSE),0) -> 0 | BT15: =IFERROR(VLOOKUP($K13,traits,BT$2,FALSE),0) -> 0 | BU15: =IFERROR(VLOOKUP($K13,traits,BU$2,FALSE),0) -> 0 | BV15: =IFERROR(VLOOKUP($K13,traits,BV$2,FALSE),0) -> 0 | BW15: =IFERROR(VLOOKUP($K13,traits,BW$2,FALSE),0) -> 0 | BX15: =IFERROR(VLOOKUP($K13,traits,BX$2,FALSE),0) -> 0 | BY15: =IFERROR(VLOOKUP($K13,traits,BY$2,FALSE),0) -> 0 | CA15: =IFERROR(VLOOKUP($L13,traits,CA$2,FALSE),0) -> 0 | CB15: =IFERROR(VLOOKUP($L13,traits,CB$2,FALSE),0) -> 0 | CC15: =IFERROR(VLOOKUP($L13,traits,CC$2,FALSE),0) -> 0 | CD15: =IFERROR(VLOOKUP($L13,traits,CD$2,FALSE),0) -> 0 | CE15: =IFERROR(VLOOKUP($L13,traits,CE$2,FALSE),0) -> 0 | CF15: =IFERROR(VLOOKUP($L13,traits,CF$2,FALSE),0) -> 0 | CG15: =IFERROR(VLOOKUP($L13,traits,CG$2,FALSE),0) -> 0 | CH15: =IFERROR(VLOOKUP($L13,traits,CH$2,FALSE),0) -> 0 | CI15: =IFERROR(VLOOKUP($L13,traits,CI$2,FALSE),0) -> 0 | CK15: =IFERROR(VLOOKUP($M13,traits,CK$2,FALSE),0) -> 0 | CL15: =IFERROR(VLOOKUP($M13,traits,CL$2,FALSE),0) -> 0 | CM15: =IFERROR(VLOOKUP($M13,traits,CM$2,FALSE),0) -> 0 | CN15: =IFERROR(VLOOKUP($M13,traits,CN$2,FALSE),0) -> 0 | CO15: =IFERROR(VLOOKUP($M13,traits,CO$2,FALSE),0) -> 0 | CP15: =IFERROR(VLOOKUP($M13,traits,CP$2,FALSE),0) -> 0 | CQ15: =IFERROR(VLOOKUP($M13,traits,CQ$2,FALSE),0) -> 0 | CR15: =IFERROR(VLOOKUP($M13,traits,CR$2,FALSE),0) -> 0 | CS15: =IFERROR(VLOOKUP($M13,traits,CS$2,FALSE),0) -> 0 | CU15: =IFERROR(VLOOKUP($N13,traits,CU$2,FALSE),0) -> 0 | CV15: =IFERROR(VLOOKUP($N13,traits,CV$2,FALSE),0) -> 0 | CW15: =IFERROR(VLOOKUP($N13,traits,CW$2,FALSE),0) -> 0 | CX15: =IFERROR(VLOOKUP($N13,traits,CX$2,FALSE),0) -> 0 | CY15: =IFERROR(VLOOKUP($N13,traits,CY$2,FALSE),0) -> 0 | CZ15: =IFERROR(VLOOKUP($N13,traits,CZ$2,FALSE),0) -> 0 | DA15: =IFERROR(VLOOKUP($N13,traits,DA$2,FALSE),0) -> 0 | DB15: =IFERROR(VLOOKUP($N13,traits,DB$2,FALSE),0) -> 0 | DC15: =IFERROR(VLOOKUP($N13,traits,DC$2,FALSE),0) -> 0 | DF15: =IFERROR(VLOOKUP($O13,Relics,DF$2,FALSE),0) -> 0 | DG15: =IFERROR(VLOOKUP($O13,Relics,DG$2,FALSE),0) -> 0 | DH15: =IFERROR(VLOOKUP($O13,Relics,DH$2,FALSE),0) -> 0 | DI15: =IFERROR(VLOOKUP($O13,Relics,DI$2,FALSE),0) -> 0 | DJ15: =IFERROR(VLOOKUP($O13,Relics,DJ$2,FALSE),0) -> 0 | DK15: =IFERROR(VLOOKUP($O13,Relics,DK$2,FALSE),0) -> 0 | DL15: =IFERROR(VLOOKUP($O13,Relics,DL$2,FALSE),0) -> 0 | DM15: =IFERROR(VLOOKUP($O13,Relics,DM$2,FALSE),0) -> 0 | DN15: =IFERROR(VLOOKUP($O13,Relics,DN$2,FALSE),0) -> 0
A16: 12 | D16: =AM18 -> 0 | E16: =AN18 -> 0 | F16: =AO18 -> 0 | G16: =AP18 -> 0 | H16: =AQ18 -> 0 | I16: =AR18 -> 0 | J16: =AS18 -> 0 | P16: =BO18+BY18+CI18+CS18+DC18+BD18 -> 0 | R16: =Q16*P16 -> 0 | U16: =IF(C16=$U$2,0,IFERROR(VLOOKUP($C16,Stats!$B$4:$B$8,1,FALSE),"Company")) -> 0 | V16: =IF(C16=$U$2,0,IFERROR(VLOOKUP(K16,Stats!$B$24:$B$27,1,FALSE),"Company")) -> 0 | W16: =IF(D16=$U$2,0,IFERROR(VLOOKUP(L16,Stats!$B$24:$B$27,1,FALSE),"Company")) -> 0 | X16: =IF(E16=$U$2,0,IFERROR(VLOOKUP(M16,Stats!$B$24:$B$27,1,FALSE),"Company")) -> 0 | Y16: =IF(F16=$U$2,0,IFERROR(VLOOKUP(N16,Stats!$B$24:$B$27,1,FALSE),"Company")) -> 0 | Z16: =COUNTIF(U16:Y16,$U$4) -> 0 | AB16: Captain | AC16: =Stats!R6 -> 3 | AD16: =Stats!T6 -> 0 | AE16: =AJ6+AJ11 -> 0 | AM16: =BH16+BR16+CB16+CL16+CV16+DG16 -> 0 | AN16: =BI16+BS16+CC16+CM16+CW16+DH16 -> 0 | AO16: =BJ16+BT16+CD16+CN16+CX16+DI16 -> 0 | AP16: =IF(MAX(BK16,BU16,CE16,CO16,CY16,DJ16)>1,MAX(BK16,BU16,CE16,CO16,CY16,DJ16),BK16+BU16+CE16+CO16+CY16+DJ16) -> 0 | AQ16: =IF(AND(C14="Ordnance battery",(OR(K14="Shooting (mixed)",L14="Shooting (mixed)",M14="Shooting (mixed)",N14="Shooting (mixed)"))),1,IF(MAX(BL16,BV16,CF16,CP16,CZ16,DK16)>1,MAX(BL16,BV16,CF16,CP16,CZ16,DK16),BL16+BV16+CF16+CP16+CZ16+DK16)) -> 0 | AR16: =BM16+BW16+CG16+CQ16+DA16+DL16 -> 0 | AS16: =BN16+BX16+CH16+CR16+DB16+DM16 -> 0 | BC16: =IFERROR(VLOOKUP($O14,Relics,BC$2,FALSE),0) -> 0 | BD16: =IFERROR(VLOOKUP($O14,Relics,BD$2,FALSE),0) -> 0 | BG16: =IFERROR(VLOOKUP($C14,stats,BG$2,FALSE),0) -> 0 | BH16: =IFERROR(VLOOKUP($C14,stats,BH$2,FALSE),0) -> 0 | BI16: =IFERROR(VLOOKUP($C14,stats,BI$2,FALSE),0) -> 0 | BJ16: =IFERROR(VLOOKUP($C14,stats,BJ$2,FALSE),0) -> 0 | BK16: =IFERROR(VLOOKUP($C14,stats,BK$2,FALSE),0) -> 0 | BL16: =IFERROR(VLOOKUP($C14,stats,BL$2,FALSE),0) -> 0 | BM16: =IFERROR(VLOOKUP($C14,stats,BM$2,FALSE),0) -> 0 | BN16: =IFERROR(VLOOKUP($C14,stats,BN$2,FALSE),0) -> 0 | BO16: =IFERROR(VLOOKUP($C14,stats,BO$2,FALSE),0) -> 0 | BQ16: =IFERROR(VLOOKUP($K14,traits,BQ$2,FALSE),0) -> 0 | BR16: =IFERROR(VLOOKUP($K14,traits,BR$2,FALSE),0) -> 0 | BS16: =IFERROR(VLOOKUP($K14,traits,BS$2,FALSE),0) -> 0 | BT16: =IFERROR(VLOOKUP($K14,traits,BT$2,FALSE),0) -> 0 | BU16: =IFERROR(VLOOKUP($K14,traits,BU$2,FALSE),0) -> 0 | BV16: =IFERROR(VLOOKUP($K14,traits,BV$2,FALSE),0) -> 0 | BW16: =IFERROR(VLOOKUP($K14,traits,BW$2,FALSE),0) -> 0 | BX16: =IFERROR(VLOOKUP($K14,traits,BX$2,FALSE),0) -> 0 | BY16: =IFERROR(VLOOKUP($K14,traits,BY$2,FALSE),0) -> 0 | CA16: =IFERROR(VLOOKUP($L14,traits,CA$2,FALSE),0) -> 0 | CB16: =IFERROR(VLOOKUP($L14,traits,CB$2,FALSE),0) -> 0 | CC16: =IFERROR(VLOOKUP($L14,traits,CC$2,FALSE),0) -> 0 | CD16: =IFERROR(VLOOKUP($L14,traits,CD$2,FALSE),0) -> 0 | CE16: =IFERROR(VLOOKUP($L14,traits,CE$2,FALSE),0) -> 0 | CF16: =IFERROR(VLOOKUP($L14,traits,CF$2,FALSE),0) -> 0 | CG16: =IFERROR(VLOOKUP($L14,traits,CG$2,FALSE),0) -> 0 | CH16: =IFERROR(VLOOKUP($L14,traits,CH$2,FALSE),0) -> 0 | CI16: =IFERROR(VLOOKUP($L14,traits,CI$2,FALSE),0) -> 0 | CK16: =IFERROR(VLOOKUP($M14,traits,CK$2,FALSE),0) -> 0 | CL16: =IFERROR(VLOOKUP($M14,traits,CL$2,FALSE),0) -> 0 | CM16: =IFERROR(VLOOKUP($M14,traits,CM$2,FALSE),0) -> 0 | CN16: =IFERROR(VLOOKUP($M14,traits,CN$2,FALSE),0) -> 0 | CO16: =IFERROR(VLOOKUP($M14,traits,CO$2,FALSE),0) -> 0 | CP16: =IFERROR(VLOOKUP($M14,traits,CP$2,FALSE),0) -> 0 | CQ16: =IFERROR(VLOOKUP($M14,traits,CQ$2,FALSE),0) -> 0 | CR16: =IFERROR(VLOOKUP($M14,traits,CR$2,FALSE),0) -> 0 | CS16: =IFERROR(VLOOKUP($M14,traits,CS$2,FALSE),0) -> 0 | CU16: =IFERROR(VLOOKUP($N14,traits,CU$2,FALSE),0) -> 0 | CV16: =IFERROR(VLOOKUP($N14,traits,CV$2,FALSE),0) -> 0 | CW16: =IFERROR(VLOOKUP($N14,traits,CW$2,FALSE),0) -> 0 | CX16: =IFERROR(VLOOKUP($N14,traits,CX$2,FALSE),0) -> 0 | CY16: =IFERROR(VLOOKUP($N14,traits,CY$2,FALSE),0) -> 0 | CZ16: =IFERROR(VLOOKUP($N14,traits,CZ$2,FALSE),0) -> 0 | DA16: =IFERROR(VLOOKUP($N14,traits,DA$2,FALSE),0) -> 0 | DB16: =IFERROR(VLOOKUP($N14,traits,DB$2,FALSE),0) -> 0 | DC16: =IFERROR(VLOOKUP($N14,traits,DC$2,FALSE),0) -> 0 | DF16: =IFERROR(VLOOKUP($O14,Relics,DF$2,FALSE),0) -> 0 | DG16: =IFERROR(VLOOKUP($O14,Relics,DG$2,FALSE),0) -> 0 | DH16: =IFERROR(VLOOKUP($O14,Relics,DH$2,FALSE),0) -> 0 | DI16: =IFERROR(VLOOKUP($O14,Relics,DI$2,FALSE),0) -> 0 | DJ16: =IFERROR(VLOOKUP($O14,Relics,DJ$2,FALSE),0) -> 0 | DK16: =IFERROR(VLOOKUP($O14,Relics,DK$2,FALSE),0) -> 0 | DL16: =IFERROR(VLOOKUP($O14,Relics,DL$2,FALSE),0) -> 0 | DM16: =IFERROR(VLOOKUP($O14,Relics,DM$2,FALSE),0) -> 0 | DN16: =IFERROR(VLOOKUP($O14,Relics,DN$2,FALSE),0) -> 0
A17: 13 | D17: =AM19 -> 0 | E17: =AN19 -> 0 | F17: =AO19 -> 0 | G17: =AP19 -> 0 | H17: =AQ19 -> 0 | I17: =AR19 -> 0 | J17: =AS19 -> 0 | P17: =BO19+BY19+CI19+CS19+DC19+BD19 -> 0 | R17: =Q17*P17 -> 0 | U17: =IF(C17=$U$2,0,IFERROR(VLOOKUP($C17,Stats!$B$4:$B$8,1,FALSE),"Company")) -> 0 | V17: =IF(C17=$U$2,0,IFERROR(VLOOKUP(K17,Stats!$B$24:$B$27,1,FALSE),"Company")) -> 0 | W17: =IF(D17=$U$2,0,IFERROR(VLOOKUP(L17,Stats!$B$24:$B$27,1,FALSE),"Company")) -> 0 | X17: =IF(E17=$U$2,0,IFERROR(VLOOKUP(M17,Stats!$B$24:$B$27,1,FALSE),"Company")) -> 0 | Y17: =IF(F17=$U$2,0,IFERROR(VLOOKUP(N17,Stats!$B$24:$B$27,1,FALSE),"Company")) -> 0 | Z17: =COUNTIF(U17:Y17,$U$4) -> 0 | AB17: Magic-user | AC17: =Stats!R7 -> 1 | AD17: =Stats!T7 -> 0 | AE17: =AJ7+AJ12 -> 0 | AM17: =BH17+BR17+CB17+CL17+CV17+DG17 -> 0 | AN17: =BI17+BS17+CC17+CM17+CW17+DH17 -> 0 | AO17: =BJ17+BT17+CD17+CN17+CX17+DI17 -> 0 | AP17: =IF(MAX(BK17,BU17,CE17,CO17,CY17,DJ17)>1,MAX(BK17,BU17,CE17,CO17,CY17,DJ17),BK17+BU17+CE17+CO17+CY17+DJ17) -> 0 | AQ17: =IF(AND(C15="Ordnance battery",(OR(K15="Shooting (mixed)",L15="Shooting (mixed)",M15="Shooting (mixed)",N15="Shooting (mixed)"))),1,IF(MAX(BL17,BV17,CF17,CP17,CZ17,DK17)>1,MAX(BL17,BV17,CF17,CP17,CZ17,DK17),BL17+BV17+CF17+CP17+CZ17+DK17)) -> 0 | AR17: =BM17+BW17+CG17+CQ17+DA17+DL17 -> 0 | AS17: =BN17+BX17+CH17+CR17+DB17+DM17 -> 0 | BC17: =IFERROR(VLOOKUP($O15,Relics,BC$2,FALSE),0) -> 0 | BD17: =IFERROR(VLOOKUP($O15,Relics,BD$2,FALSE),0) -> 0 | BG17: =IFERROR(VLOOKUP($C15,stats,BG$2,FALSE),0) -> 0 | BH17: =IFERROR(VLOOKUP($C15,stats,BH$2,FALSE),0) -> 0 | BI17: =IFERROR(VLOOKUP($C15,stats,BI$2,FALSE),0) -> 0 | BJ17: =IFERROR(VLOOKUP($C15,stats,BJ$2,FALSE),0) -> 0 | BK17: =IFERROR(VLOOKUP($C15,stats,BK$2,FALSE),0) -> 0 | BL17: =IFERROR(VLOOKUP($C15,stats,BL$2,FALSE),0) -> 0 | BM17: =IFERROR(VLOOKUP($C15,stats,BM$2,FALSE),0) -> 0 | BN17: =IFERROR(VLOOKUP($C15,stats,BN$2,FALSE),0) -> 0 | BO17: =IFERROR(VLOOKUP($C15,stats,BO$2,FALSE),0) -> 0 | BQ17: =IFERROR(VLOOKUP($K15,traits,BQ$2,FALSE),0) -> 0 | BR17: =IFERROR(VLOOKUP($K15,traits,BR$2,FALSE),0) -> 0 | BS17: =IFERROR(VLOOKUP($K15,traits,BS$2,FALSE),0) -> 0 | BT17: =IFERROR(VLOOKUP($K15,traits,BT$2,FALSE),0) -> 0 | BU17: =IFERROR(VLOOKUP($K15,traits,BU$2,FALSE),0) -> 0 | BV17: =IFERROR(VLOOKUP($K15,traits,BV$2,FALSE),0) -> 0 | BW17: =IFERROR(VLOOKUP($K15,traits,BW$2,FALSE),0) -> 0 | BX17: =IFERROR(VLOOKUP($K15,traits,BX$2,FALSE),0) -> 0 | BY17: =IFERROR(VLOOKUP($K15,traits,BY$2,FALSE),0) -> 0 | CA17: =IFERROR(VLOOKUP($L15,traits,CA$2,FALSE),0) -> 0 | CB17: =IFERROR(VLOOKUP($L15,traits,CB$2,FALSE),0) -> 0 | CC17: =IFERROR(VLOOKUP($L15,traits,CC$2,FALSE),0) -> 0 | CD17: =IFERROR(VLOOKUP($L15,traits,CD$2,FALSE),0) -> 0 | CE17: =IFERROR(VLOOKUP($L15,traits,CE$2,FALSE),0) -> 0 | CF17: =IFERROR(VLOOKUP($L15,traits,CF$2,FALSE),0) -> 0 | CG17: =IFERROR(VLOOKUP($L15,traits,CG$2,FALSE),0) -> 0 | CH17: =IFERROR(VLOOKUP($L15,traits,CH$2,FALSE),0) -> 0 | CI17: =IFERROR(VLOOKUP($L15,traits,CI$2,FALSE),0) -> 0 | CK17: =IFERROR(VLOOKUP($M15,traits,CK$2,FALSE),0) -> 0 | CL17: =IFERROR(VLOOKUP($M15,traits,CL$2,FALSE),0) -> 0 | CM17: =IFERROR(VLOOKUP($M15,traits,CM$2,FALSE),0) -> 0 | CN17: =IFERROR(VLOOKUP($M15,traits,CN$2,FALSE),0) -> 0 | CO17: =IFERROR(VLOOKUP($M15,traits,CO$2,FALSE),0) -> 0 | CP17: =IFERROR(VLOOKUP($M15,traits,CP$2,FALSE),0) -> 0 | CQ17: =IFERROR(VLOOKUP($M15,traits,CQ$2,FALSE),0) -> 0 | CR17: =IFERROR(VLOOKUP($M15,traits,CR$2,FALSE),0) -> 0 | CS17: =IFERROR(VLOOKUP($M15,traits,CS$2,FALSE),0) -> 0 | CU17: =IFERROR(VLOOKUP($N15,traits,CU$2,FALSE),0) -> 0 | CV17: =IFERROR(VLOOKUP($N15,traits,CV$2,FALSE),0) -> 0 | CW17: =IFERROR(VLOOKUP($N15,traits,CW$2,FALSE),0) -> 0 | CX17: =IFERROR(VLOOKUP($N15,traits,CX$2,FALSE),0) -> 0 | CY17: =IFERROR(VLOOKUP($N15,traits,CY$2,FALSE),0) -> 0 | CZ17: =IFERROR(VLOOKUP($N15,traits,CZ$2,FALSE),0) -> 0 | DA17: =IFERROR(VLOOKUP($N15,traits,DA$2,FALSE),0) -> 0 | DB17: =IFERROR(VLOOKUP($N15,traits,DB$2,FALSE),0) -> 0 | DC17: =IFERROR(VLOOKUP($N15,traits,DC$2,FALSE),0) -> 0 | DF17: =IFERROR(VLOOKUP($O15,Relics,DF$2,FALSE),0) -> 0 | DG17: =IFERROR(VLOOKUP($O15,Relics,DG$2,FALSE),0) -> 0 | DH17: =IFERROR(VLOOKUP($O15,Relics,DH$2,FALSE),0) -> 0 | DI17: =IFERROR(VLOOKUP($O15,Relics,DI$2,FALSE),0) -> 0 | DJ17: =IFERROR(VLOOKUP($O15,Relics,DJ$2,FALSE),0) -> 0 | DK17: =IFERROR(VLOOKUP($O15,Relics,DK$2,FALSE),0) -> 0 | DL17: =IFERROR(VLOOKUP($O15,Relics,DL$2,FALSE),0) -> 0 | DM17: =IFERROR(VLOOKUP($O15,Relics,DM$2,FALSE),0) -> 0 | DN17: =IFERROR(VLOOKUP($O15,Relics,DN$2,FALSE),0) -> 0
